Workbook

Sheet Executive Dashboard
B1: STARBUCKS COFFEE COMPANY — TPLH FORECAST & LABOR BALANCING (2021–2036)
B2: Baza Wieloletnia • Silnik Predykcyjny Trendów Transakcji (Trend Velocity) • Dynamiczne Bilansowanie Grafiku (HANW) • Ochrona Floor Hours
B3: 📥 IMPORTUJ LOGOWANIA (MAPAL) | F3: 📊 EDYTUJ BAZĘ AOP (PLAN) | J3: 📋 POKAŻ BAZĘ LOGOWAŃ (RCP DB) | O3: ⚙️ FLOOR HOURS ENGINE | Q3: 🔒 UKRYJ ARKUSZE
B4: 1. PLAN AOP NA MIESIĄC | F4: 2. WYKONANIE MTD & TREND | J4: 3. LIMIT NA KOLEJNY GRAFIK (HANW) | O4: 4. OCHRONA MINIMUM (FLOOR HOURS)
B5: Wybierz Rok: | C5: 2026 | F5: Godziny Przepracowane: | G5: =J18 | J5: HANW na Kolejny Tydzień: | L5: ='Buffer Engine'!B3 | O5: Floor Hours Tygodnia: | P5: ='Buffer Engine'!B5
B6: Wybierz Miesiąc: | C6: Wrzesień | F6: Odchylenie Godzin (+/-): | G6: =M18 | J6: Wymagana Zmiana vs Plan: | L6: ='Buffer Engine'!B4 | O6: Margines nad Floor: | P6: ='Buffer Engine'!B6
B7: Cel TPLH AOP: | C7: ='Labor Engine'!E4 | F7: Rzeczywisty TPLH MTD: | G7: =L18 | J7: Wypracowany Budżet Mies.: | L7: ='Forecast Engine'!$B$10 | O7: Status Bezpieczeństwa: | P7: ='Alert Engine'!B1
B8: Budżet Godzin AOP: | C8: ='Labor Engine'!E3 | F8: Trend Transakcji MTD: | G8: ='Forecast Engine'!$B$8 - 1 | J8: Wpływ Trendu na Budżet: | L8: ='Forecast Engine'!$B$11 | O8: Floor Hours Miesiąca: | P8: =P18
B9: Plan TRX AOP: | C9: ='Labor Engine'!H3 | F9: Zamknięte Tygodnie: | G9: ='Forecast Engine'!$B$5 | J9: Pozostały Budżet Earned: | L9: ='Forecast Engine'!$B$12 | O9: Liczba Tygodni w Miesiącu: | P9: ='Labor Engine'!B5
B10: TABELA TYGODNIOWA — PLAN AOP, WYKONANIE RZECZYWISTE I PREDYKCJA NA KOLEJNY GRAFIK
B11: Tydzień | C11: Zakres Dat | D11: Dni | E11: Typ Tygodnia | F11: Plan TRX | G11: Actual TRX | H11: Trend TRX | I11: Plan Godziny | J11: Actual Godziny | K11: Cel TPLH | L11: Actual TPLH | M11: Odchylenie (+/-) | N11: Prognoza TRX | O11: HANW Predykcyjny | P11: Floor Hours | Q11: Status Floor
B12: ='Forecast Engine'!A15 | C12: ='Labor Engine'!B10 | D12: ='Forecast Engine'!B15 | E12: ='Forecast Engine'!C15 | F12: ='Forecast Engine'!D15 | G12: 2050 | H12: ='Forecast Engine'!F15 | I12: ='Forecast Engine'!G15 | J12: =IF(SUMIFS('Labor Actuals DB'!$K:$K, 'Labor Actuals DB'!$F:$F, $C$5 & "_" & $C$6 & "_W1")>0, ROUND(SUMIFS('Labor Actuals DB'!$K:$K, 'Labor Actuals DB'!$F:$F, $C$5 & "_" & $C$6 & "_W1"), 1), "") | K12: ='Forecast Engine'!I15 | L12: ='Forecast Engine'!J15 | M12: ='Forecast Engine'!K15 | N12: ='Forecast Engine'!M15 | O12: ='Forecast Engine'!Q15 | P12: ='Forecast Engine'!P15 | Q12: ='Forecast Engine'!R15
B13: ='Forecast Engine'!A16 | C13: ='Labor Engine'!B11 | D13: ='Forecast Engine'!B16 | E13: ='Forecast Engine'!C16 | F13: ='Forecast Engine'!D16 | H13: ='Forecast Engine'!F16 | I13: ='Forecast Engine'!G16 | J13: =IF(SUMIFS('Labor Actuals DB'!$K:$K, 'Labor Actuals DB'!$F:$F, $C$5 & "_" & $C$6 & "_W2")>0, ROUND(SUMIFS('Labor Actuals DB'!$K:$K, 'Labor Actuals DB'!$F:$F, $C$5 & "_" & $C$6 & "_W2"), 1), "") | K13: ='Forecast Engine'!I16 | L13: ='Forecast Engine'!J16 | M13: ='Forecast Engine'!K16 | N13: ='Forecast Engine'!M16 | O13: ='Forecast Engine'!Q16 | P13: ='Forecast Engine'!P16 | Q13: ='Forecast Engine'!R16
B14: ='Forecast Engine'!A17 | C14: ='Labor Engine'!B12 | D14: ='Forecast Engine'!B17 | E14: ='Forecast Engine'!C17 | F14: ='Forecast Engine'!D17 | H14: ='Forecast Engine'!F17 | I14: ='Forecast Engine'!G17 | J14: =IF(SUMIFS('Labor Actuals DB'!$K:$K, 'Labor Actuals DB'!$F:$F, $C$5 & "_" & $C$6 & "_W3")>0, ROUND(SUMIFS('Labor Actuals DB'!$K:$K, 'Labor Actuals DB'!$F:$F, $C$5 & "_" & $C$6 & "_W3"), 1), "") | K14: ='Forecast Engine'!I17 | L14: ='Forecast Engine'!J17 | M14: ='Forecast Engine'!K17 | N14: ='Forecast Engine'!M17 | O14: ='Forecast Engine'!Q17 | P14: ='Forecast Engine'!P17 | Q14: ='Forecast Engine'!R17
B15: ='Forecast Engine'!A18 | C15: ='Labor Engine'!B13 | D15: ='Forecast Engine'!B18 | E15: ='Forecast Engine'!C18 | F15: ='Forecast Engine'!D18 | H15: ='Forecast Engine'!F18 | I15: ='Forecast Engine'!G18 | J15: =IF(SUMIFS('Labor Actuals DB'!$K:$K, 'Labor Actuals DB'!$F:$F, $C$5 & "_" & $C$6 & "_W4")>0, ROUND(SUMIFS('Labor Actuals DB'!$K:$K, 'Labor Actuals DB'!$F:$F, $C$5 & "_" & $C$6 & "_W4"), 1), "") | K15: ='Forecast Engine'!I18 | L15: ='Forecast Engine'!J18 | M15: ='Forecast Engine'!K18 | N15: ='Forecast Engine'!M18 | O15: ='Forecast Engine'!Q18 | P15: ='Forecast Engine'!P18 | Q15: ='Forecast Engine'!R18
B16: ='Forecast Engine'!A19 | C16: ='Labor Engine'!B14 | D16: ='Forecast Engine'!B19 | E16: ='Forecast Engine'!C19 | F16: ='Forecast Engine'!D19 | H16: ='Forecast Engine'!F19 | I16: ='Forecast Engine'!G19 | J16: =IF(SUMIFS('Labor Actuals DB'!$K:$K, 'Labor Actuals DB'!$F:$F, $C$5 & "_" & $C$6 & "_W5")>0, ROUND(SUMIFS('Labor Actuals DB'!$K:$K, 'Labor Actuals DB'!$F:$F, $C$5 & "_" & $C$6 & "_W5"), 1), "") | K16: ='Forecast Engine'!I19 | L16: ='Forecast Engine'!J19 | M16: ='Forecast Engine'!K19 | N16: ='Forecast Engine'!M19 | O16: ='Forecast Engine'!Q19 | P16: ='Forecast Engine'!P19 | Q16: ='Forecast Engine'!R19
B17: ='Forecast Engine'!A20 | C17: ='Labor Engine'!B15 | D17: ='Forecast Engine'!B20 | E17: ='Forecast Engine'!C20 | F17: ='Forecast Engine'!D20 | H17: ='Forecast Engine'!F20 | I17: ='Forecast Engine'!G20 | J17: =IF(SUMIFS('Labor Actuals DB'!$K:$K, 'Labor Actuals DB'!$F:$F, $C$5 & "_" & $C$6 & "_W6")>0, ROUND(SUMIFS('Labor Actuals DB'!$K:$K, 'Labor Actuals DB'!$F:$F, $C$5 & "_" & $C$6 & "_W6"), 1), "") | K17: ='Forecast Engine'!I20 | L17: ='Forecast Engine'!J20 | M17: ='Forecast Engine'!K20 | N17: ='Forecast Engine'!M20 | O17: ='Forecast Engine'!Q20 | P17: ='Forecast Engine'!P20 | Q17: ='Forecast Engine'!R20
B18: SUMA MIESIĄCA | D18: =SUM(D12:D17) | F18: =SUM(F12:F17) | G18: =SUM(G12:G17) | H18: ='Forecast Engine'!$B$8 - 1 | I18: =SUM(I12:I17) | J18: =SUM(J12:J17) | K18: ='Labor Engine'!E4 | L18: =IF(J18=0, "", ROUND(G18/J18, 2)) | M18: =SUM(M12:M17) | N18: ='Forecast Engine'!$B$9 | O18: =SUM(O12:O17) | P18: =SUM(P12:P17)
B20: REKOMENDACJA OPERACYJNA DLA STORE MANAGERA: | E20: ='Alert Engine'!B2

Sheet Calendar Engine
A1: Date | B1: Week Start | C1: Week End | D1: Business Week | E1: Rok | F1: Miesiąc | G1: Dzień Tygodnia | H1: Floor Hours Dnia | I1: Tydzień w Miesiącu | J1: Klucz Tygodnia (Y_M_W)
A2: 44197 | B2: 44194 | C2: 44200 | D2: BW20201229 | E2: 2021 | F2: Styczeń | G2: Pt | H2: ='Floor Hours Engine'!$E$5 | I2: W1 | J2: 2021_Styczeń_W1
A3: 44198 | B3: 44194 | C3: 44200 | D3: BW20201229 | E3: 2021 | F3: Styczeń | G3: Sob | H3: ='Floor Hours Engine'!$E$5 | I3: W1 | J3: 2021_Styczeń_W1
A4: 44199 | B4: 44194 | C4: 44200 | D4: BW20201229 | E4: 2021 | F4: Styczeń | G4: Nd | H4: ='Floor Hours Engine'!$E$6 | I4: W1 | J4: 2021_Styczeń_W1
A5: 44200 | B5: 44194 | C5: 44200 | D5: BW20201229 | E5: 2021 | F5: Styczeń | G5: Pn | H5: ='Floor Hours Engine'!$E$4 | I5: W1 | J5: 2021_Styczeń_W1
A6: 44201 | B6: 44201 | C6: 44207 | D6: BW20210105 | E6: 2021 | F6: Styczeń | G6: Wt | H6: ='Floor Hours Engine'!$E$4 | I6: W2 | J6: 2021_Styczeń_W2
A7: 44202 | B7: 44201 | C7: 44207 | D7: BW20210105 | E7: 2021 | F7: Styczeń | G7: Śr | H7: ='Floor Hours Engine'!$E$4 | I7: W2 | J7: 2021_Styczeń_W2
A8: 44203 | B8: 44201 | C8: 44207 | D8: BW20210105 | E8: 2021 | F8: Styczeń | G8: Czw | H8: ='Floor Hours Engine'!$E$4 | I8: W2 | J8: 2021_Styczeń_W2
A9: 44204 | B9: 44201 | C9: 44207 | D9: BW20210105 | E9: 2021 | F9: Styczeń | G9: Pt | H9: ='Floor Hours Engine'!$E$5 | I9: W2 | J9: 2021_Styczeń_W2
A10: 44205 | B10: 44201 | C10: 44207 | D10: BW20210105 | E10: 2021 | F10: Styczeń | G10: Sob | H10: ='Floor Hours Engine'!$E$5 | I10: W2 | J10: 2021_Styczeń_W2
A11: 44206 | B11: 44201 | C11: 44207 | D11: BW20210105 | E11: 2021 | F11: Styczeń | G11: Nd | H11: ='Floor Hours Engine'!$E$6 | I11: W2 | J11: 2021_Styczeń_W2
A12: 44207 | B12: 44201 | C12: 44207 | D12: BW20210105 | E12: 2021 | F12: Styczeń | G12: Pn | H12: ='Floor Hours Engine'!$E$4 | I12: W2 | J12: 2021_Styczeń_W2
A13: 44208 | B13: 44208 | C13: 44214 | D13: BW20210112 | E13: 2021 | F13: Styczeń | G13: Wt | H13: ='Floor Hours Engine'!$E$4 | I13: W3 | J13: 2021_Styczeń_W3
A14: 44209 | B14: 44208 | C14: 44214 | D14: BW20210112 | E14: 2021 | F14: Styczeń | G14: Śr | H14: ='Floor Hours Engine'!$E$4 | I14: W3 | J14: 2021_Styczeń_W3
A15: 44210 | B15: 44208 | C15: 44214 | D15: BW20210112 | E15: 2021 | F15: Styczeń | G15: Czw | H15: ='Floor Hours Engine'!$E$4 | I15: W3 | J15: 2021_Styczeń_W3
A16: 44211 | B16: 44208 | C16: 44214 | D16: BW20210112 | E16: 2021 | F16: Styczeń | G16: Pt | H16: ='Floor Hours Engine'!$E$5 | I16: W3 | J16: 2021_Styczeń_W3
A17: 44212 | B17: 44208 | C17: 44214 | D17: BW20210112 | E17: 2021 | F17: Styczeń | G17: Sob | H17: ='Floor Hours Engine'!$E$5 | I17: W3 | J17: 2021_Styczeń_W3
A18: 44213 | B18: 44208 | C18: 44214 | D18: BW20210112 | E18: 2021 | F18: Styczeń | G18: Nd | H18: ='Floor Hours Engine'!$E$6 | I18: W3 | J18: 2021_Styczeń_W3
A19: 44214 | B19: 44208 | C19: 44214 | D19: BW20210112 | E19: 2021 | F19: Styczeń | G19: Pn | H19: ='Floor Hours Engine'!$E$4 | I19: W3 | J19: 2021_Styczeń_W3
A20: 44215 | B20: 44215 | C20: 44221 | D20: BW20210119 | E20: 2021 | F20: Styczeń | G20: Wt | H20: ='Floor Hours Engine'!$E$4 | I20: W4 | J20: 2021_Styczeń_W4
A21: 44216 | B21: 44215 | C21: 44221 | D21: BW20210119 | E21: 2021 | F21: Styczeń | G21: Śr | H21: ='Floor Hours Engine'!$E$4 | I21: W4 | J21: 2021_Styczeń_W4
A22: 44217 | B22: 44215 | C22: 44221 | D22: BW20210119 | E22: 2021 | F22: Styczeń | G22: Czw | H22: ='Floor Hours Engine'!$E$4 | I22: W4 | J22: 2021_Styczeń_W4
A23: 44218 | B23: 44215 | C23: 44221 | D23: BW20210119 | E23: 2021 | F23: Styczeń | G23: Pt | H23: ='Floor Hours Engine'!$E$5 | I23: W4 | J23: 2021_Styczeń_W4
A24: 44219 | B24: 44215 | C24: 44221 | D24: BW20210119 | E24: 2021 | F24: Styczeń | G24: Sob | H24: ='Floor Hours Engine'!$E$5 | I24: W4 | J24: 2021_Styczeń_W4
A25: 44220 | B25: 44215 | C25: 44221 | D25: BW20210119 | E25: 2021 | F25: Styczeń | G25: Nd | H25: ='Floor Hours Engine'!$E$6 | I25: W4 | J25: 2021_Styczeń_W4
A26: 44221 | B26: 44215 | C26: 44221 | D26: BW20210119 | E26: 2021 | F26: Styczeń | G26: Pn | H26: ='Floor Hours Engine'!$E$4 | I26: W4 | J26: 2021_Styczeń_W4
A27: 44222 | B27: 44222 | C27: 44228 | D27: BW20210126 | E27: 2021 | F27: Styczeń | G27: Wt | H27: ='Floor Hours Engine'!$E$4 | I27: W5 | J27: 2021_Styczeń_W5
A28: 44223 | B28: 44222 | C28: 44228 | D28: BW20210126 | E28: 2021 | F28: Styczeń | G28: Śr | H28: ='Floor Hours Engine'!$E$4 | I28: W5 | J28: 2021_Styczeń_W5
A29: 44224 | B29: 44222 | C29: 44228 | D29: BW20210126 | E29: 2021 | F29: Styczeń | G29: Czw | H29: ='Floor Hours Engine'!$E$4 | I29: W5 | J29: 2021_Styczeń_W5
A30: 44225 | B30: 44222 | C30: 44228 | D30: BW20210126 | E30: 2021 | F30: Styczeń | G30: Pt | H30: ='Floor Hours Engine'!$E$5 | I30: W5 | J30: 2021_Styczeń_W5
A31: 44226 | B31: 44222 | C31: 44228 | D31: BW20210126 | E31: 2021 | F31: Styczeń | G31: Sob | H31: ='Floor Hours Engine'!$E$5 | I31: W5 | J31: 2021_Styczeń_W5
A32: 44227 | B32: 44222 | C32: 44228 | D32: BW20210126 | E32: 2021 | F32: Styczeń | G32: Nd | H32: ='Floor Hours Engine'!$E$6 | I32: W5 | J32: 2021_Styczeń_W5
A33: 44228 | B33: 44222 | C33: 44228 | D33: BW20210126 | E33: 2021 | F33: Luty | G33: Pn | H33: ='Floor Hours Engine'!$E$4 | I33: W1 | J33: 2021_Luty_W1
A34: 44229 | B34: 44229 | C34: 44235 | D34: BW20210202 | E34: 2021 | F34: Luty | G34: Wt | H34: ='Floor Hours Engine'!$E$4 | I34: W2 | J34: 2021_Luty_W2
A35: 44230 | B35: 44229 | C35: 44235 | D35: BW20210202 | E35: 2021 | F35: Luty | G35: Śr | H35: ='Floor Hours Engine'!$E$4 | I35: W2 | J35: 2021_Luty_W2
A36: 44231 | B36: 44229 | C36: 44235 | D36: BW20210202 | E36: 2021 | F36: Luty | G36: Czw | H36: ='Floor Hours Engine'!$E$4 | I36: W2 | J36: 2021_Luty_W2
A37: 44232 | B37: 44229 | C37: 44235 | D37: BW20210202 | E37: 2021 | F37: Luty | G37: Pt | H37: ='Floor Hours Engine'!$E$5 | I37: W2 | J37: 2021_Luty_W2
A38: 44233 | B38: 44229 | C38: 44235 | D38: BW20210202 | E38: 2021 | F38: Luty | G38: Sob | H38: ='Floor Hours Engine'!$E$5 | I38: W2 | J38: 2021_Luty_W2
A39: 44234 | B39: 44229 | C39: 44235 | D39: BW20210202 | E39: 2021 | F39: Luty | G39: Nd | H39: ='Floor Hours Engine'!$E$6 | I39: W2 | J39: 2021_Luty_W2
A40: 44235 | B40: 44229 | C40: 44235 | D40: BW20210202 | E40: 2021 | F40: Luty | G40: Pn | H40: ='Floor Hours Engine'!$E$4 | I40: W2 | J40: 2021_Luty_W2
...

Sheet AOP Plan Master
A1: AOP PLAN MASTER — CAŁOROCZNA BAZA PLANU (2021–2036) | E1: ⬅️ POWRÓT DO EXECUTIVE DASHBOARD (UKRYJ ARKUSZ)
B2: Wybierz Rok do Podglądu: | C2: 2026 | E2: Suma Plan TRX Roku: | F2: =SUMIFS($F$5:$F$196, $B$5:$B$196, $C$2) | H2: Budżet Godzin Roku: | I2: =SUMIFS($H$5:$H$196, $B$5:$B$196, $C$2)
A4: Klucz (Y_M) | B4: Rok | C4: Miesiąc | D4: Nr Miesiąca | E4: Liczba Tygodni | F4: Plan Transakcji (AOP TRX) | G4: Cel TPLH AOP | H4: Budżet Godzin AOP | I4: Średni Budżet / Tydz.
A5: 2021_Styczeń | B5: 2021 | C5: Styczeń | D5: M01 | E5: 5 | F5: 10800 | G5: 7.2 | H5: =ROUND(F5/G5, 1) | I5: =ROUND(H5/E5, 1)
A6: 2021_Luty | B6: 2021 | C6: Luty | D6: M02 | E6: 5 | F6: 10350 | G6: 7.2 | H6: =ROUND(F6/G6, 1) | I6: =ROUND(H6/E6, 1)
A7: 2021_Marzec | B7: 2021 | C7: Marzec | D7: M03 | E7: 6 | F7: 11700 | G7: 7.2 | H7: =ROUND(F7/G7, 1) | I7: =ROUND(H7/E7, 1)
A8: 2021_Kwiecień | B8: 2021 | C8: Kwiecień | D8: M04 | E8: 5 | F8: 11520 | G8: 7.2 | H8: =ROUND(F8/G8, 1) | I8: =ROUND(H8/E8, 1)
A9: 2021_Maj | B9: 2021 | C9: Maj | D9: M05 | E9: 5 | F9: 12150 | G9: 7.2 | H9: =ROUND(F9/G9, 1) | I9: =ROUND(H9/E9, 1)
A10: 2021_Czerwiec | B10: 2021 | C10: Czerwiec | D10: M06 | E10: 5 | F10: 12600 | G10: 7.2 | H10: =ROUND(F10/G10, 1) | I10: =ROUND(H10/E10, 1)
A11: 2021_Lipiec | B11: 2021 | C11: Lipiec | D11: M07 | E11: 5 | F11: 12780 | G11: 7.2 | H11: =ROUND(F11/G11, 1) | I11: =ROUND(H11/E11, 1)
A12: 2021_Sierpień | B12: 2021 | C12: Sierpień | D12: M08 | E12: 6 | F12: 12420 | G12: 7.2 | H12: =ROUND(F12/G12, 1) | I12: =ROUND(H12/E12, 1)
A13: 2021_Wrzesień | B13: 2021 | C13: Wrzesień | D13: M09 | E13: 5 | F13: 11880 | G13: 7.2 | H13: =ROUND(F13/G13, 1) | I13: =ROUND(H13/E13, 1)
A14: 2021_Październik | B14: 2021 | C14: Październik | D14: M10 | E14: 5 | F14: 11700 | G14: 7.2 | H14: =ROUND(F14/G14, 1) | I14: =ROUND(H14/E14, 1)
A15: 2021_Listopad | B15: 2021 | C15: Listopad | D15: M11 | E15: 6 | F15: 12150 | G15: 7.2 | H15: =ROUND(F15/G15, 1) | I15: =ROUND(H15/E15, 1)
A16: 2021_Grudzień | B16: 2021 | C16: Grudzień | D16: M12 | E16: 5 | F16: 13950 | G16: 7.2 | H16: =ROUND(F16/G16, 1) | I16: =ROUND(H16/E16, 1)
... A196: 2036_Grudzień | B196: 2036 | C196: Grudzień | D196: M12 | E196: 6 | F196: 18600 | G196: 7.2 | H196: =ROUND(F196/G196, 1) | I196: =ROUND(H196/E196, 1)

Sheet Forecast Engine
A1: Miesiąc | B1: ='Labor Engine'!B4
A2: Cel TPLH AOP | B2: ='Labor Engine'!E4
A3: Budżet Godzin AOP | B3: ='Labor Engine'!E3
A4: Plan TRX AOP Miesiąca | B4: ='Labor Engine'!H3
A5: Liczba Zamkniętych Tygodni | B5: =COUNT('Executive Dashboard'!J12:J17)
A6: TRX MTD Plan (Zamknięte Tygodnie) | B6: =SUMIF('Executive Dashboard'!J12:J17, ">0", 'Executive Dashboard'!F12:F17)
A7: TRX MTD Actual (Zamknięte Tygodnie) | B7: =SUMIF('Executive Dashboard'!J12:J17, ">0", 'Executive Dashboard'!G12:G17)
A8: Wskaźnik Trendu TRX MTD | B8: =IF(B6=0, 1, ROUND(B7/B6, 4))
A9: Forecast Total TRX na Miesiąc | B9: =SUM(M15:M20)
A10: Earned Labor Budget na Miesiąc | B10: =ROUND(B9/B2, 1)
A11: Wpływ Trendu na Budżet Godzin (+/-) | B11: =ROUND(B10-B3, 1)
A12: Pozostały Budżet Wypracowany (Remaining Earned Hours) | B12: =B10 - SUM('Executive Dashboard'!J12:J17)
A13: Suma Otwartej Prognozy TRX | B13: =SUM(L15:L20)
A14: Tydzień | B14: Liczba Dni | C14: Typ Tygodnia | D14: Plan TRX AOP | E14: Actual TRX | F14: Trend TRX | G14: Plan Godziny AOP | H14: Actual Godziny | I14: Cel TPLH AOP | J14: Actual TPLH | K14: Odchylenie Godzin | L14: Otwarty Forecast TRX | M14: Prognoza TRX Total | N14: Waga Otwarta TRX | O14: HANW Predykcyjny | P14: Floor Hours | Q14: HANW Rekomendowany | R14: Status Floor
A15: W1 | B15: ='Labor Engine'!C10 | C15: ='Labor Engine'!D10 | D15: ='Labor Engine'!E10 | E15: =IF('Executive Dashboard'!G12="", "", 'Executive Dashboard'!G12) | F15: =IF(B15=0, "-", IF(ISNUMBER(E15), ROUND((E15-D15)/D15, 4), "")) | G15: ='Labor Engine'!F10 | H15: =IF('Executive Dashboard'!J12="", "", 'Executive Dashboard'!J12) | I15: ='Labor Engine'!G10 | J15: =IF(B15=0, "-", IF(AND(ISNUMBER(H15), H15>0, ISNUMBER(E15)), ROUND(E15/H15, 2), "")) | K15: =IF(B15=0, "-", IF(AND(ISNUMBER(H15), H15>0), ROUND(H15-G15, 1), "")) | L15: =IF(B15=0, 0, IF(ISNUMBER(H15), 0, ROUND(D15*$B$8, 0))) | M15: =IF(B15=0, 0, IF(ISNUMBER(E15), E15, ROUND(D15*$B$8, 0))) | N15: =IF(B15=0, 0, IF(ISNUMBER(H15), 0, L15/MAX(1, $B$13))) | O15: =IF(B15=0, 0, IF(ISNUMBER(H15), H15, ROUND($B$12 * N15, 1))) | P15: ='Labor Engine'!M10 | Q15: =IF(B15=0, 0, IF(ISNUMBER(H15), H15, MAX(P15, O15))) | R15: =IF(B15=0, "-", IF(ISNUMBER(H15), "Zrealizowany", IF(O15<P15, "ALERT: Floor Breach!", "OK: Bezpiecznie")))
A16: W2 | B16: ='Labor Engine'!C11 | C16: ='Labor Engine'!D11 | D16: ='Labor Engine'!E11 | E16: =IF('Executive Dashboard'!G13="", "", 'Executive Dashboard'!G13) | F16: =IF(B16=0, "-", IF(ISNUMBER(E16), ROUND((E16-D16)/D16, 4), "")) | G16: ='Labor Engine'!F11 | H16: =IF('Executive Dashboard'!J13="", "", 'Executive Dashboard'!J13) | I16: ='Labor Engine'!G11 | J16: =IF(B16=0, "-", IF(AND(ISNUMBER(H16), H16>0, ISNUMBER(E16)), ROUND(E16/H16, 2), "")) | K16: =IF(B16=0, "-", IF(AND(ISNUMBER(H16), H16>0), ROUND(H16-G16, 1), "")) | L16: =IF(B16=0, 0, IF(ISNUMBER(H16), 0, ROUND(D16*$B$8, 0))) | M16: =IF(B16=0, 0, IF(ISNUMBER(E16), E16, ROUND(D16*$B$8, 0))) | N16: =IF(B16=0, 0, IF(ISNUMBER(H16), 0, L16/MAX(1, $B$13))) | O16: =IF(B16=0, 0, IF(ISNUMBER(H16), H16, ROUND($B$12 * N16, 1))) | P16: ='Labor Engine'!M11 | Q16: =IF(B16=0, 0, IF(ISNUMBER(H16), H16, MAX(P16, O16))) | R16: =IF(B16=0, "-", IF(ISNUMBER(H16), "Zrealizowany", IF(O16<P16, "ALERT: Floor Breach!", "OK: Bezpiecznie")))
A17: W3 | B17: ='Labor Engine'!C12 | C17: ='Labor Engine'!D12 | D17: ='Labor Engine'!E12 | E17: =IF('Executive Dashboard'!G14="", "", 'Executive Dashboard'!G14) | F17: =IF(B17=0, "-", IF(ISNUMBER(E17), ROUND((E17-D17)/D17, 4), "")) | G17: ='Labor Engine'!F12 | H17: =IF('Executive Dashboard'!J14="", "", 'Executive Dashboard'!J14) | I17: ='Labor Engine'!G12 | J17: =IF(B17=0, "-", IF(AND(ISNUMBER(H17), H17>0, ISNUMBER(E17)), ROUND(E17/H17, 2), "")) | K17: =IF(B17=0, "-", IF(AND(ISNUMBER(H17), H17>0), ROUND(H17-G17, 1), "")) | L17: =IF(B17=0, 0, IF(ISNUMBER(H17), 0, ROUND(D17*$B$8, 0))) | M17: =IF(B17=0, 0, IF(ISNUMBER(E17), E17, ROUND(D17*$B$8, 0))) | N17: =IF(B17=0, 0, IF(ISNUMBER(H17), 0, L17/MAX(1, $B$13))) | O17: =IF(B17=0, 0, IF(ISNUMBER(H17), H17, ROUND($B$12 * N17, 1))) | P17: ='Labor Engine'!M12 | Q17: =IF(B17=0, 0, IF(ISNUMBER(H17), H17, MAX(P17, O17))) | R17: =IF(B17=0, "-", IF(ISNUMBER(H17), "Zrealizowany", IF(O17<P17, "ALERT: Floor Breach!", "OK: Bezpiecznie")))
A18: W4 | B18: ='Labor Engine'!C13 | C18: ='Labor Engine'!D13 | D18: ='Labor Engine'!E13 | E18: =IF('Executive Dashboard'!G15="", "", 'Executive Dashboard'!G15) | F18: =IF(B18=0, "-", IF(ISNUMBER(E18), ROUND((E18-D18)/D18, 4), "")) | G18: ='Labor Engine'!F13 | H18: =IF('Executive Dashboard'!J15="", "", 'Executive Dashboard'!J15) | I18: ='Labor Engine'!G13 | J18: =IF(B18=0, "-", IF(AND(ISNUMBER(H18), H18>0, ISNUMBER(E18)), ROUND(E18/H18, 2), "")) | K18: =IF(B18=0, "-", IF(AND(ISNUMBER(H18), H18>0), ROUND(H18-G18, 1), "")) | L18: =IF(B18=0, 0, IF(ISNUMBER(H18), 0, ROUND(D18*$B$8, 0))) | M18: =IF(B18=0, 0, IF(ISNUMBER(E18), E18, ROUND(D18*$B$8, 0))) | N18: =IF(B18=0, 0, IF(ISNUMBER(H18), 0, L18/MAX(1, $B$13))) | O18: =IF(B18=0, 0, IF(ISNUMBER(H18), H18, ROUND($B$12 * N18, 1))) | P18: ='Labor Engine'!M13 | Q18: =IF(B18=0, 0, IF(ISNUMBER(H18), H18, MAX(P18, O18))) | R18: =IF(B18=0, "-", IF(ISNUMBER(H18), "Zrealizowany", IF(O18<P18, "ALERT: Floor Breach!", "OK: Bezpiecznie")))
A19: W5 | B19: ='Labor Engine'!C14 | C19: ='Labor Engine'!D14 | D19: ='Labor Engine'!E14 | E19: =IF('Executive Dashboard'!G16="", "", 'Executive Dashboard'!G16) | F19: =IF(B19=0, "-", IF(ISNUMBER(E19), ROUND((E19-D19)/D19, 4), "")) | G19: ='Labor Engine'!F14 | H19: =IF('Executive Dashboard'!J16="", "", 'Executive Dashboard'!J16) | I19: ='Labor Engine'!G14 | J19: =IF(B19=0, "-", IF(AND(ISNUMBER(H19), H19>0, ISNUMBER(E19)), ROUND(E19/H19, 2), "")) | K19: =IF(B19=0, "-", IF(AND(ISNUMBER(H19), H19>0), ROUND(H19-G19, 1), "")) | L19: =IF(B19=0, 0, IF(ISNUMBER(H19), 0, ROUND(D19*$B$8, 0))) | M19: =IF(B19=0, 0, IF(ISNUMBER(E19), E19, ROUND(D19*$B$8, 0))) | N19: =IF(B19=0, 0, IF(ISNUMBER(H19), 0, L19/MAX(1, $B$13))) | O19: =IF(B19=0, 0, IF(ISNUMBER(H19), H19, ROUND($B$12 * N19, 1))) | P19: ='Labor Engine'!M14 | Q19: =IF(B19=0, 0, IF(ISNUMBER(H19), H19, MAX(P19, O19))) | R19: =IF(B19=0, "-", IF(ISNUMBER(H19), "Zrealizowany", IF(O19<P19, "ALERT: Floor Breach!", "OK: Bezpiecznie")))
A20: W6 | B20: ='Labor Engine'!C15 | C20: ='Labor Engine'!D15 | D20: ='Labor Engine'!E15 | E20: =IF('Executive Dashboard'!G17="", "", 'Executive Dashboard'!G17) | F20: =IF(B20=0, "-", IF(ISNUMBER(E20), ROUND((E20-D20)/D20, 4), "")) | G20: ='Labor Engine'!F15 | H20: =IF('Executive Dashboard'!J17="", "", 'Executive Dashboard'!J17) | I20: ='Labor Engine'!G15 | J20: =IF(B20=0, "-", IF(AND(ISNUMBER(H20), H20>0, ISNUMBER(E20)), ROUND(E20/H20, 2), "")) | K20: =IF(B20=0, "-", IF(AND(ISNUMBER(H20), H20>0), ROUND(H20-G20, 1), "")) | L20: =IF(B20=0, 0, IF(ISNUMBER(H20), 0, ROUND(D20*$B$8, 0))) | M20: =IF(B20=0, 0, IF(ISNUMBER(E20), E20, ROUND(D20*$B$8, 0))) | N20: =IF(B20=0, 0, IF(ISNUMBER(H20), 0, L20/MAX(1, $B$13))) | O20: =IF(B20=0, 0, IF(ISNUMBER(H20), H20, ROUND($B$12 * N20, 1))) | P20: ='Labor Engine'!M15 | Q20: =IF(B20=0, 0, IF(ISNUMBER(H20), H20, MAX(P20, O20))) | R20: =IF(B20=0, "-", IF(ISNUMBER(H20), "Zrealizowany", IF(O20<P20, "ALERT: Floor Breach!", "OK: Bezpiecznie")))

Sheet Labor Engine
A1: Labor Engine — Silnik Balansowania Tygodniowego AOP
A2: Aktywny Rok | B2: ='Executive Dashboard'!C5
A3: Aktywny Miesiąc | B3: ='Executive Dashboard'!C6 | D3: Budżet Godzin AOP | E3: =VLOOKUP($B$4, 'AOP Plan Master'!$A:$H, 8, FALSE) | G3: Plan TRX AOP | H3: =VLOOKUP($B$4, 'AOP Plan Master'!$A:$F, 6, FALSE)
A4: Aktywny Klucz Miesiąca (Y_M) | B4: =$B$2 & "_" & $B$3 | D4: Cel TPLH AOP | E4: =VLOOKUP($B$4, 'AOP Plan Master'!$A:$G, 7, FALSE)
A5: Liczba Tygodni w Miesiącu | B5: =VLOOKUP($B$4, 'AOP Plan Master'!$A:$E, 5, FALSE)
A9: Tydzień | B9: Zakres Dat | C9: Liczba Dni | D9: Typ Tygodnia | E9: Plan TRX Tygodnia | F9: Plan AOP Godziny | G9: Cel TPLH AOP | H9: Waga Dniowa | I9: Actual Godziny | J9: Actual TPLH | K9: Odchylenie (+/-) | L9: HANW Skorygowany | M9: Floor Hours | N9: Weryfikacja Floor | O9: Waga Otwarta
A10: W1 | B10: =IF(VLOOKUP(CONCATENATE($B$4, "_W1"), 'Weeks Engine'!$A:$E, 5, FALSE)=0, "-", VLOOKUP(CONCATENATE($B$4, "_W1"), 'Weeks Engine'!$A:$G, 7, FALSE) & " - " & VLOOKUP(CONCATENATE($B$4, "_W1"), 'Weeks Engine'!$A:$H, 8, FALSE)) | C10: =VLOOKUP(CONCATENATE($B$4, "_W1"), 'Weeks Engine'!$A:$E, 5, FALSE) | D10: =VLOOKUP(CONCATENATE($B$4, "_W1"), 'Weeks Engine'!$A:$F, 6, FALSE) | E10: =ROUND($H$3 * H10, 0) | F10: =ROUND($E$3 * H10, 1) | G10: =IF(C10=0, "-", $E$4) | H10: =VLOOKUP(CONCATENATE($B$4, "_W1"), 'Weeks Engine'!$A:$J, 10, FALSE) | I10: =IF('Executive Dashboard'!J12="", "", 'Executive Dashboard'!J12) | J10: =IF(C10=0, "-", IF(AND(ISNUMBER(I10), I10>0), ROUND(E10/I10, 2), "")) | K10: =IF(C10=0, "-", IF(AND(ISNUMBER(I10), I10>0), ROUND(I10-F10, 1), "")) | L10: =IF(C10=0, 0, IF(ISNUMBER(I10), I10, ROUND(($E$3 - SUM($I$10:$I$15)) * (H10 / MAX(0.0001, $O$16)), 1))) | M10: =VLOOKUP(CONCATENATE($B$4, "_W1"), 'Weeks Engine'!$A:$I, 9, FALSE) | N10: =IF(C10=0, "-", IF(ISNUMBER(I10), "Zrealizowany", IF(L10<M10, "ALERT: Poniżej Floor!", "OK: Bezpiecznie"))) | O10: =IF(C10=0, 0, IF(ISNUMBER(I10), 0, H10))
A11: W2 | B11: =IF(VLOOKUP(CONCATENATE($B$4, "_W2"), 'Weeks Engine'!$A:$E, 5, FALSE)=0, "-", VLOOKUP(CONCATENATE($B$4, "_W2"), 'Weeks Engine'!$A:$G, 7, FALSE) & " - " & VLOOKUP(CONCATENATE($B$4, "_W2"), 'Weeks Engine'!$A:$H, 8, FALSE)) | C11: =VLOOKUP(CONCATENATE($B$4, "_W2"), 'Weeks Engine'!$A:$E, 5, FALSE) | D11: =VLOOKUP(CONCATENATE($B$4, "_W2"), 'Weeks Engine'!$A:$F, 6, FALSE) | E11: =ROUND($H$3 * H11, 0) | F11: =ROUND($E$3 * H11, 1) | G11: =IF(C11=0, "-", $E$4) | H11: =VLOOKUP(CONCATENATE($B$4, "_W2"), 'Weeks Engine'!$A:$J, 10, FALSE) | I11: =IF('Executive Dashboard'!J13="", "", 'Executive Dashboard'!J13) | J11: =IF(C11=0, "-", IF(AND(ISNUMBER(I11), I11>0), ROUND(E11/I11, 2), "")) | K11: =IF(C11=0, "-", IF(AND(ISNUMBER(I11), I11>0), ROUND(I11-F11, 1), "")) | L11: =IF(C11=0, 0, IF(ISNUMBER(I11), I11, ROUND(($E$3 - SUM($I$10:$I$15)) * (H11 / MAX(0.0001, $O$16)), 1))) | M11: =VLOOKUP(CONCATENATE($B$4, "_W2"), 'Weeks Engine'!$A:$I, 9, FALSE) | N11: =IF(C11=0, "-", IF(ISNUMBER(I11), "Zrealizowany", IF(L11<M11, "ALERT: Poniżej Floor!", "OK: Bezpiecznie"))) | O11: =IF(C11=0, 0, IF(ISNUMBER(I11), 0, H11))
A12: W3 | B12: =IF(VLOOKUP(CONCATENATE($B$4, "_W3"), 'Weeks Engine'!$A:$E, 5, FALSE)=0, "-", VLOOKUP(CONCATENATE($B$4, "_W3"), 'Weeks Engine'!$A:$G, 7, FALSE) & " - " & VLOOKUP(CONCATENATE($B$4, "_W3"), 'Weeks Engine'!$A:$H, 8, FALSE)) | C12: =VLOOKUP(CONCATENATE($B$4, "_W3"), 'Weeks Engine'!$A:$E, 5, FALSE) | D12: =VLOOKUP(CONCATENATE($B$4, "_W3"), 'Weeks Engine'!$A:$F, 6, FALSE) | E12: =ROUND($H$3 * H12, 0) | F12: =ROUND($E$3 * H12, 1) | G12: =IF(C12=0, "-", $E$4) | H12: =VLOOKUP(CONCATENATE($B$4, "_W3"), 'Weeks Engine'!$A:$J, 10, FALSE) | I12: =IF('Executive Dashboard'!J14="", "", 'Executive Dashboard'!J14) | J12: =IF(C12=0, "-", IF(AND(ISNUMBER(I12), I12>0), ROUND(E12/I12, 2), "")) | K12: =IF(C12=0, "-", IF(AND(ISNUMBER(I12), I12>0), ROUND(I12-F12, 1), "")) | L12: =IF(C12=0, 0, IF(ISNUMBER(I12), I12, ROUND(($E$3 - SUM($I$10:$I$15)) * (H12 / MAX(0.0001, $O$16)), 1))) | M12: =VLOOKUP(CONCATENATE($B$4, "_W3"), 'Weeks Engine'!$A:$I, 9, FALSE) | N12: =IF(C12=0, "-", IF(ISNUMBER(I12), "Zrealizowany", IF(L12<M12, "ALERT: Poniżej Floor!", "OK: Bezpiecznie"))) | O12: =IF(C12=0, 0, IF(ISNUMBER(I12), 0, H12))
A13: W4 | B13: =IF(VLOOKUP(CONCATENATE($B$4, "_W4"), 'Weeks Engine'!$A:$E, 5, FALSE)=0, "-", VLOOKUP(CONCATENATE($B$4, "_W4"), 'Weeks Engine'!$A:$G, 7, FALSE) & " - " & VLOOKUP(CONCATENATE($B$4, "_W4"), 'Weeks Engine'!$A:$H, 8, FALSE)) | C13: =VLOOKUP(CONCATENATE($B$4, "_W4"), 'Weeks Engine'!$A:$E, 5, FALSE) | D13: =VLOOKUP(CONCATENATE($B$4, "_W4"), 'Weeks Engine'!$A:$F, 6, FALSE) | E13: =ROUND($H$3 * H13, 0) | F13: =ROUND($E$3 * H13, 1) | G13: =IF(C13=0, "-", $E$4) | H13: =VLOOKUP(CONCATENATE($B$4, "_W4"), 'Weeks Engine'!$A:$J, 10, FALSE) | I13: =IF('Executive Dashboard'!J15="", "", 'Executive Dashboard'!J15) | J13: =IF(C13=0, "-", IF(AND(ISNUMBER(I13), I13>0), ROUND(E13/I13, 2), "")) | K13: =IF(C13=0, "-", IF(AND(ISNUMBER(I13), I13>0), ROUND(I13-F13, 1), "")) | L13: =IF(C13=0, 0, IF(ISNUMBER(I13), I13, ROUND(($E$3 - SUM($I$10:$I$15)) * (H13 / MAX(0.0001, $O$16)), 1))) | M13: =VLOOKUP(CONCATENATE($B$4, "_W4"), 'Weeks Engine'!$A:$I, 9, FALSE) | N13: =IF(C13=0, "-", IF(ISNUMBER(I13), "Zrealizowany", IF(L13<M13, "ALERT: Poniżej Floor!", "OK: Bezpiecznie"))) | O13: =IF(C13=0, 0, IF(ISNUMBER(I13), 0, H13))
A14: W5 | B14: =IF(VLOOKUP(CONCATENATE($B$4, "_W5"), 'Weeks Engine'!$A:$E, 5, FALSE)=0, "-", VLOOKUP(CONCATENATE($B$4, "_W5"), 'Weeks Engine'!$A:$G, 7, FALSE) & " - " & VLOOKUP(CONCATENATE($B$4, "_W5"), 'Weeks Engine'!$A:$H, 8, FALSE)) | C14: =VLOOKUP(CONCATENATE($B$4, "_W5"), 'Weeks Engine'!$A:$E, 5, FALSE) | D14: =VLOOKUP(CONCATENATE($B$4, "_W5"), 'Weeks Engine'!$A:$F, 6, FALSE) | E14: =ROUND($H$3 * H14, 0) | F14: =ROUND($E$3 * H14, 1) | G14: =IF(C14=0, "-", $E$4) | H14: =VLOOKUP(CONCATENATE($B$4, "_W5"), 'Weeks Engine'!$A:$J, 10, FALSE) | I14: =IF('Executive Dashboard'!J16="", "", 'Executive Dashboard'!J16) | J14: =IF(C14=0, "-", IF(AND(ISNUMBER(I14), I14>0), ROUND(E14/I14, 2), "")) | K14: =IF(C14=0, "-", IF(AND(ISNUMBER(I14), I14>0), ROUND(I14-F14, 1), "")) | L14: =IF(C14=0, 0, IF(ISNUMBER(I14), I14, ROUND(($E$3 - SUM($I$10:$I$15)) * (H14 / MAX(0.0001, $O$16)), 1))) | M14: =VLOOKUP(CONCATENATE($B$4, "_W5"), 'Weeks Engine'!$A:$I, 9, FALSE) | N14: =IF(C14=0, "-", IF(ISNUMBER(I14), "Zrealizowany", IF(L14<M14, "ALERT: Poniżej Floor!", "OK: Bezpiecznie"))) | O14: =IF(C14=0, 0, IF(ISNUMBER(I14), 0, H14))
A15: W6 | B15: =IF(VLOOKUP(CONCATENATE($B$4, "_W6"), 'Weeks Engine'!$A:$E, 5, FALSE)=0, "-", VLOOKUP(CONCATENATE($B$4, "_W6"), 'Weeks Engine'!$A:$G, 7, FALSE) & " - " & VLOOKUP(CONCATENATE($B$4, "_W6"), 'Weeks Engine'!$A:$H, 8, FALSE)) | C15: =VLOOKUP(CONCATENATE($B$4, "_W6"), 'Weeks Engine'!$A:$E, 5, FALSE) | D15: =VLOOKUP(CONCATENATE($B$4, "_W6"), 'Weeks Engine'!$A:$F, 6, FALSE) | E15: =ROUND($H$3 * H15, 0) | F15: =ROUND($E$3 * H15, 1) | G15: =IF(C15=0, "-", $E$4) | H15: =VLOOKUP(CONCATENATE($B$4, "_W6"), 'Weeks Engine'!$A:$J, 10, FALSE) | I15: =IF('Executive Dashboard'!J17="", "", 'Executive Dashboard'!J17) | J15: =IF(C15=0, "-", IF(AND(ISNUMBER(I15), I15>0), ROUND(E15/I15, 2), "")) | K15: =IF(C15=0, "-", IF(AND(ISNUMBER(I15), I15>0), ROUND(I15-F15, 1), "")) | L15: =IF(C15=0, 0, IF(ISNUMBER(I15), I15, ROUND(($E$3 - SUM($I$10:$I$15)) * (H15 / MAX(0.0001, $O$16)), 1))) | M15: =VLOOKUP(CONCATENATE($B$4, "_W6"), 'Weeks Engine'!$A:$I, 9, FALSE) | N15: =IF(C15=0, "-", IF(ISNUMBER(I15), "Zrealizowany", IF(L15<M15, "ALERT: Poniżej Floor!", "OK: Bezpiecznie"))) | O15: =IF(C15=0, 0, IF(ISNUMBER(I15), 0, H15))
A16: SUMA MIESIĄCA | C16: =SUM(C10:C15) | E16: =SUM(E10:E15) | F16: =SUM(F10:F15) | G16: =ROUND(E16/F16, 2) | I16: =SUM(I10:I15) | J16: =IF(I16=0, "", ROUND(SUMIF(I10:I15, ">0", E10:E15)/I16, 2)) | K16: =SUM(K10:K15) | L16: =SUM(L10:L15) | M16: =SUM(M10:M15) | O16: =SUM(O10:O15)

Sheet Buffer Engine
A1: Remaining Budget Hours | B1: ='Labor Engine'!$E$3 - SUM('Executive Dashboard'!$J$12:$J$17)
A2: Buffer Hours MTD | B2: ='Forecast Engine'!$B$12
A3: HANW (Godziny na Najbliższy Otwarty Tydzień) | B3: =IF(COUNT('Executive Dashboard'!$J$12:$J$17) >= 'Labor Engine'!$B$5, "Miesiąc zamknięty", INDEX('Forecast Engine'!$Q$15:$Q$20, COUNT('Executive Dashboard'!$J$12:$J$17) + 1))
A4: Wymagana Redukcja na Najbliższy Tydzień | B4: =IF(COUNT('Executive Dashboard'!$J$12:$J$17) >= 'Labor Engine'!$B$5, "-", ROUND(INDEX('Forecast Engine'!$Q$15:$Q$20, COUNT('Executive Dashboard'!$J$12:$J$17) + 1) - INDEX('Labor Engine'!$F$10:$F$15, COUNT('Executive Dashboard'!$J$12:$J$17) + 1), 1))
A5: Floor Hours Najbliższego Tygodnia | B5: =IF(COUNT('Executive Dashboard'!$J$12:$J$17) >= 'Labor Engine'!$B$5, "-", INDEX('Forecast Engine'!$P$15:$P$20, COUNT('Executive Dashboard'!$J$12:$J$17) + 1))
A6: Margines Bezpieczeństwa nad Floor | B6: =IF(OR(B3="Miesiąc zamknięty", B5="-"), "-", ROUND(B3 - B5, 1))

Sheet Alert Engine
A1: Status Operacyjny | B1: =IF('Buffer Engine'!B3="Miesiąc zamknięty", "ZAKOŃCZONY", IF('Buffer Engine'!B3 < 'Buffer Engine'!B5, "CRITICAL: Poniżej Floor Hours!", IF('Forecast Engine'!$B$8 < 0.98, "UWAGA: Spadek sprzedaży", IF('Forecast Engine'!$B$8 > 1.02, "BOOM: Wypracowano dodatkowe godziny", "ON TRACK"))))
A2: Rekomendacja dla Store Managera | B2: =IF('Buffer Engine'!B3="Miesiąc zamknięty", "Wszystkie tygodnie miesiąca zostały zrealizowane zgodnie z AOP.", IF('Forecast Engine'!$B$8 < 0.98, "UWAGA: Trend transakcji wynosi " & ROUND(('Forecast Engine'!$B$8-1)*100, 1) & "%. Skoryguj grafik na kolejny tydzień do " & 'Buffer Engine'!B3 & " h (redukcja o " & -'Buffer Engine'!B4 & " h względem planu AOP). Floor Hours zachowane.", IF('Forecast Engine'!$B$8 > 1.02, "POZYTYWNY TREND: Transakcje rosną o +" & ROUND(('Forecast Engine'!$B$8-1)*100, 1) & "% (wypracowano +" & 'Forecast Engine'!$B$11 & " h). Możesz zaplanować w grafiku " & 'Buffer Engine'!B3 & " h (+ " & 'Buffer Engine'!B4 & " h względem bazowego AOP).", "Transakcje stabilne (trend " & ROUND('Forecast Engine'!$B$8*100, 1) & "%). Zaplanuj w kolejnym grafiku dokładnie " & 'Buffer Engine'!B3 & " h.")))

Sheet Floor Hours Engine
A1: Floor Hours Engine — Minimalna Obsada Operacyjna Kawiarni (Starbucks) | D1: ⬅️ POWRÓT DO EXECUTIVE DASHBOARD (UKRYJ ARKUSZ)
A3: Dni tygodnia | B3: Dni w tyg. | C3: Liczba zmian/osób | D3: Godziny na zmianę | E3: Godziny dziennie | F3: Godziny tygodniowo
A4: Poniedziałek - Czwartek | B4: 4 | C4: 5 | D4: 8 | E4: =C4*D4 | F4: =B4*E4
A5: Piątek - Sobota | B5: 2 | C5: 5 | D5: 8 | E5: =C5*D5 | F5: =B5*E5
A6: Niedziela | B6: 1 | C6: 4 | D6: 8 | E6: =C6*D6 | F6: =B6*E6
A7: MINIMALNE GODZINY TYGODNIOWE (FLOOR) | F7: =SUM(F4:F6)
A9: Instrukcja / Wskazówki operacyjne:
A10: 1. Zielone komórki (Liczba zmian/osób oraz Godziny na zmianę) są w pełni edytowalne przez Store Managera.
A11: 2. Minimalne godziny tygodniowe (Floor Hours, komórka F7) chronią kawiarnię przed zaplanowaniem obsady zagrażającej otwarciu, zamknięciu lub standardom obsługi.

Sheet Weeks Engine
A1: Weeks Engine — Wieloletnie Rozbicie Tygodni i Floor Hours (2021–2036)
A3: Klucz (Y_M_W) | B3: Rok | C3: Miesiąc | D3: Tydzień | E3: Liczba Dni | F3: Typ Tygodnia | G3: Data Od | H3: Data Do | I3: Floor Hours Tygodnia | J3: Waga Dniowa w Miesiącu
A4: 2021_Styczeń_W1 | B4: 2021 | C4: Styczeń | D4: W1 | E4: 4 | F4: Niepełny (4 dni) | G4: 01.01 | H4: 04.01 | I4: 152 | J4: 0.12903
A5: 2021_Styczeń_W2 | B5: 2021 | C5: Styczeń | D5: W2 | E5: 7 | F5: Pełny (7 dni) | G5: 05.01 | H5: 11.01 | I5: 272 | J5: 0.22581
A6: 2021_Styczeń_W3 | B6: 2021 | C6: Styczeń | D6: W3 | E6: 7 | F6: Pełny (7 dni) | G6: 12.01 | H6: 18.01 | I6: 272 | J6: 0.22581
A7: 2021_Styczeń_W4 | B7: 2021 | C7: Styczeń | D7: W4 | E7: 7 | F7: Pełny (7 dni) | G7: 19.01 | H7: 25.01 | I7: 272 | J7: 0.22581
A8: 2021_Styczeń_W5 | B8: 2021 | C8: Styczeń | D8: W5 | E8: 6 | F8: Niepełny (6 dni) | G8: 26.01 | H8: 31.01 | I8: 232 | J8: 0.19355
A9: 2021_Styczeń_W6 | B9: 2021 | C9: Styczeń | D9: W6 | E9: 0 | F9: Brak w miesiącu | G9: - | H9: - | I9: 0 | J9: 0
A10: 2021_Luty_W1 | B10: 2021 | C10: Luty | D10: W1 | E10: 1 | F10: Niepełny (1 dni) | G10: 01.02 | H10: 01.02 | I10: 40 | J10: 0.03571
A11: 2021_Luty_W2 | B11: 2021 | C11: Luty | D11: W2 | E11: 7 | F11: Pełny (7 dni) | G11: 02.02 | H11: 08.02 | I11: 272 | J11: 0.25
A12: 2021_Luty_W3 | B12: 2021 | C12: Luty | D12: W3 | E12: 7 | F12: Pełny (7 dni) | G12: 09.02 | H12: 15.02 | I12: 272 | J12: 0.25
A13: 2021_Luty_W4 | B13: 2021 | C13: Luty | D13: W4 | E13: 7 | F13: Pełny (7 dni) | G13: 16.02 | H13: 22.02 | I13: 272 | J13: 0.25
A14: 2021_Luty_W5 | B14: 2021 | C14: Luty | D14: W5 | E14: 6 | F14: Niepełny (6 dni) | G14: 23.02 | H14: 28.02 | I14: 232 | J14: 0.21429
A15: 2021_Luty_W6 | B15: 2021 | C15: Luty | D15: W6 | E15: 0 | F15: Brak w miesiącu | G15: - | H15: - | I15: 0 | J15: 0
... A1155: 2036_Grudzień_W6 | B1155: 2036 | C1155: Grudzień | D1155: W6 | E1155: 2 | F1155: Niepełny (2 dni) | G1155: 30.12 | H1155: 31.12 | I1155: 80 | J1155: 0.06452

Sheet Labor Actuals DB
A1: ID | B1: Data | C1: Rok | D1: Miesiąc | E1: Tydzień | F1: Klucz_Tygodnia | G1: Dzień | H1: Pracownik | I1: Stanowisko | J1: Wymiar_Etatu | K1: Godziny | L1: Kawiarnia_Kod | M1: Kawiarnia_Nazwa | N1: Data_Importu | O1: ⬅️ POWRÓT DO DASHBOARDU
A2: 1 | B2: 2026-06-01 | C2: 2026 | D2: Czerwiec | E2: W1 | F2: 2026_Czerwiec_W1 | G2: Pn | H2: APEL, DAWID | I2: Assistant Manager | J2: Standard 1,0|40h | K2: 8 | L2: 384 | M2: 108120 SBX Warszawa Janki | N2: 2026-09-11 19:06
A3: 2 | B3: 2026-06-02 | C3: 2026 | D3: Czerwiec | E3: W2 | F3: 2026_Czerwiec_W2 | G3: Wt | H3: APEL, DAWID | I3: Assistant Manager | J3: Standard 1,0|40h | K3: 7.75 | L3: 384 | M3: 108120 SBX Warszawa Janki | N3: 2026-09-11 19:06
A4: 3 | B4: 2026-06-03 | C4: 2026 | D4: Czerwiec | E4: W2 | F4: 2026_Czerwiec_W2 | G4: Śr | H4: APEL, DAWID | I4: Assistant Manager | J4: Standard 1,0|40h | K4: 7.81 | L4: 384 | M4: 108120 SBX Warszawa Janki | N4: 2026-09-11 19:06
A5: 4 | B5: 2026-06-04 | C5: 2026 | D5: Czerwiec | E5: W2 | F5: 2026_Czerwiec_W2 | G5: Czw | H5: APEL, DAWID | I5: Assistant Manager | J5: Standard 1,0|40h | K5: 4.63 | L5: 384 | M5: 108120 SBX Warszawa Janki | N5: 2026-09-11 19:06
A6: 5 | B6: 2026-06-05 | C6: 2026 | D6: Czerwiec | E6: W2 | F6: 2026_Czerwiec_W2 | G6: Pt | H6: APEL, DAWID | I6: Assistant Manager | J6: Standard 1,0|40h | K6: 7.9 | L6: 384 | M6: 108120 SBX Warszawa Janki | N6: 2026-09-11 19:06
A7: 6 | B7: 2026-06-09 | C7: 2026 | D7: Czerwiec | E7: W3 | F7: 2026_Czerwiec_W3 | G7: Wt | H7: APEL, DAWID | I7: Assistant Manager | J7: Standard 1,0|40h | K7: 8 | L7: 384 | M7: 108120 SBX Warszawa Janki | N7: 2026-09-11 19:06
A8: 7 | B8: 2026-06-11 | C8: 2026 | D8: Czerwiec | E8: W3 | F8: 2026_Czerwiec_W3 | G8: Czw | H8: APEL, DAWID | I8: Assistant Manager | J8: Standard 1,0|40h | K8: 8 | L8: 384 | M8: 108120 SBX Warszawa Janki | N8: 2026-09-11 19:06
A9: 8 | B9: 2026-06-15 | C9: 2026 | D9: Czerwiec | E9: W3 | F9: 2026_Czerwiec_W3 | G9: Pn | H9: APEL, DAWID | I9: Assistant Manager | J9: Standard 1,0|40h | K9: 8 | L9: 384 | M9: 108120 SBX Warszawa Janki | N9: 2026-09-11 19:06
A10: 9 | B10: 2026-06-16 | C10: 2026 | D10: Czerwiec | E10: W4 | F10: 2026_Czerwiec_W4 | G10: Wt | H10: APEL, DAWID | I10: Assistant Manager | J10: Standard 1,0|40h | K10: 8 | L10: 384 | M10: 108120 SBX Warszawa Janki | N10: 2026-09-11 19:06
A11: 10 | B11: 2026-06-19 | C11: 2026 | D11: Czerwiec | E11: W4 | F11: 2026_Czerwiec_W4 | G11: Pt | H11: APEL, DAWID | I11: Assistant Manager | J11: Standard 1,0|40h | K11: 8.05 | L11: 384 | M11: 108120 SBX Warszawa Janki | N11: 2026-09-11 19:06
A12: 11 | B12: 2026-06-22 | C12: 2026 | D12: Czerwiec | E12: W4 | F12: 2026_Czerwiec_W4 | G12: Pn | H12: APEL, DAWID | I12: Assistant Manager | J12: Standard 1,0|40h | K12: 9.17 | L12: 384 | M12: 108120 SBX Warszawa Janki | N12: 2026-09-11 19:06
A13: 12 | B13: 2026-06-23 | C13: 2026 | D13: Czerwiec | E13: W5 | F13: 2026_Czerwiec_W5 | G13: Wt | H13: APEL, DAWID | I13: Assistant Manager | J13: Standard 1,0|40h | K13: 8 | L13: 384 | M13: 108120 SBX Warszawa Janki | N13: 2026-09-11 19:06
... A1688: 1687 | B1688: 2026-09-03 | C1688: 2026 | D1688: Wrzesień | E1688: W1 | F1688: 2026_Wrzesień_W1 | G1688: Czw | H1688: ZNOJEK, GABRIELA | I1688: Shift manager/Supervisor | J1688: Standard 1,0|40h | K1688: 6.65 | L1688: 384 | M1688: 108120 SBX Warszawa Janki | N1688: 2026-09-11 19:06
