Workbook
Name MATRIX_PLAN: DANE!$Q$4:$Q$6
Name ON: DANE!$P$10

Sheet USER GUIDE
A1: SUPPORT
A2: W przypadku kłopotów lub pytań - napisz do maciej.andrzejewski@amrest.eu załączając plik, którego używasz wraz z opisem tego co się stało.
A4: W całym pliku uzupełniaj tylko żółte pola. Większość pól ma opis w komentarzu, który wyjaśnia skąd bierze się jakaś wartość lub jak jest obliczana. Wszystkie księgowania i obliczenia są potwierdzone z Payroll.
A5: Po tym jak zaplanujesz dany miesiąc kliknij Plik > Zapisz jako > MPK_Nazwamiesiąca
A6: Wklejanie AOP oraz Planu TPLH
A7: W Amreport wygeneruj dane AOP, koniecznie z rozwiniętymi wszystkimi kategoriami COL, a następnie wyeksportuj go do excela.
A8: Otwórz pobrany plik a następnie kliknij w lewym górnym rogu aby zaznaczyć cały arkusz i naciśnij CTRL+C
A9: Otwórz zakładkę AOP w kalkulatorze kosztów pracy. Kliknij w komórkę A1 w lewym górnym rogu a następnie wklej AOP skrótem klawiaturowym CTRL+V
A11: Przejdź do arkusza TPLH PLAN i wklej otrzymany od DM plan TPLH na cały rok. Wklejając użyj funkcji "wklej wartości".
A13: Planowanie nowego miesiąca - TARGET
A14: W żółtym polu z listy rozwijanej wybierz swój numer MPK
A16: Z listy rozwijanej wybierz miesiąc, który chcesz zaplanować. Wprowadź ilość dni otwartej kawiarni w miesiącu.
... A83: Wersja do druku jest wyskalowana do poniższego widoku. Pozostałe strony nie będą się drukować.

Sheet Rezerwa urlopowa
B1: Krok 1
B3: Korzystając z raportu P&L, przejdź do G&L Listingu w na koncie Payroll Manager
B18: Krok 2
B20: Przepisz kwotę rezerwy z poprzedniego miesiąca w poniższą tabelkę
B29: Krok 3
B31: Przejdź do AmReports -> Online Reports -> Monthly Reports -> Urlopy
B55: Do tabelki poniżej przepisz wartosci z kolumny "Urlop Rezerwa (na dd.mm.rrrr)" dla SM i podwładnych.
A78: NARZĘDZIE
B80: UZUPEŁNIJ tylko żółte pola
B82: MPK restauracji | C82: =CALCULATOR!F1 -> 108120
B83: Nazwa restauracji | C83: =CALCULATOR!C1 -> SBX Warszawa Janki
B84: rezerwa na miesiąc | C84: =CALCULATOR!C5 -> WRZESIEŃ
A86: lp. | B86: Nazwisko i Imię pracownika | C86: ilość dni urlopu niewykorzystanego /dni/ | D86: stawka miesięczna wynagrodzenia brutto /zł/ | E86: kwota rezerwy konto księgowe 40510610 | F86: składka ZUS konto księgowe 40610110 | G86: RAZEM rezerwa na niewykorzystany urlop (Razem rezerwa + ZUS)
A87: 1 | B87: =IF(CALCULATOR!I3="","",CALCULATOR!I3) -> Dawid Szeluga | C87: 2 | D87: =CALCULATOR!L3*CALCULATOR!K3 -> 7200 | E87: =ROUND((D87/21)*C87,0) -> 686 | F87: =ROUND(E87*0.195,0) -> 134 | G87: =E87+F87 -> 820
A88: 2 | B88: =IF(CALCULATOR!I4="","",CALCULATOR!I4) -> Dawid Apel | C88: 4 | D88: =CALCULATOR!L4*CALCULATOR!K4 -> 6300 | E88: =ROUND((D88/21)*C88,0) -> 1200 | F88: =ROUND(E88*0.195,0) -> 234 | G88: =E88+F88 -> 1434
A89: 3 | B89: =IF(CALCULATOR!I5="","",CALCULATOR!I5) -> Zuzanna Makowska | C89: 1 | D89: =CALCULATOR!L5*CALCULATOR!K5 -> 2632.5 | E89: =ROUND((D89/21)*C89,0) -> 125 | F89: =ROUND(E89*0.195,0) -> 24 | G89: =E89+F89 -> 149
A90: 4 | B90: =IF(CALCULATOR!I6="","",CALCULATOR!I6) -> Weronika Bieńkowska | C90: 4 | D90: =CALCULATOR!L6*CALCULATOR!K6 -> 2800 | E90: =ROUND((D90/21)*C90,0) -> 533 | F90: =ROUND(E90*0.195,0) -> 104 | G90: =E90+F90 -> 637
A91: 5 | B91: =IF(CALCULATOR!I7="","",CALCULATOR!I7) -> Nikola Studzińska | C91: 4 | D91: =CALCULATOR!L7*CALCULATOR!K7 -> 1150 | E91: =ROUND((D91/21)*C91,0) -> 219 | F91: =ROUND(E91*0.195,0) -> 43 | G91: =E91+F91 -> 262
A92: 6 | B92: =IF(CALCULATOR!I8="","",CALCULATOR!I8) -> Kamil Kamiński | D92: =CALCULATOR!L8*CALCULATOR!K8 -> 5600 | E92: =ROUND((D92/21)*C92,0) -> 0 | F92: =ROUND(E92*0.195,0) -> 0 | G92: =E92+F92 -> 0
A93: 7 | B93: =IF(CALCULATOR!I9="","",CALCULATOR!I9) | D93: =CALCULATOR!L9*CALCULATOR!K9 -> 0 | E93: =ROUND((D93/21)*C93,0) -> 0 | F93: =ROUND(E93*0.195,0) -> 0 | G93: =E93+F93 -> 0
A94: 8 | B94: =IF(CALCULATOR!I10="","",CALCULATOR!I10) | D94: =CALCULATOR!L10*CALCULATOR!K10 -> 0 | E94: =ROUND((D94/21)*C94,0) -> 0 | F94: =ROUND(E94*0.195,0) -> 0 | G94: =E94+F94 -> 0
A95: 9 | B95: =IF(CALCULATOR!I11="","",CALCULATOR!I11) | D95: =CALCULATOR!L11*CALCULATOR!K11 -> 0 | E95: =ROUND((D95/21)*C95,0) -> 0 | F95: =ROUND(E95*0.195,0) -> 0 | G95: =E95+F95 -> 0
A96: 10 | B96: =IF(CALCULATOR!I12="","",CALCULATOR!I12) | D96: =CALCULATOR!L12*CALCULATOR!K12 -> 0 | E96: =ROUND((D96/21)*C96,0) -> 0 | F96: =ROUND(E96*0.195,0) -> 0 | G96: =E96+F96 -> 0
A97: 11 | B97: Manager Bench | D97: =CALCULATOR!L13*CALCULATOR!K13 -> 0 | E97: =ROUND((D97/21)*C97,0) -> 0 | F97: =ROUND(E97*0.195,0) -> 0 | G97: =E97+F97 -> 0
A98: 12 | B98: Manager Maternity | E98: =ROUND((D98/21)*C98,0) -> 0 | F98: =ROUND(E98*0.195,0) -> 0 | G98: =E98+F98 -> 0
A99: 13 | B99: Manager Maternity | E99: =ROUND((D99/21)*C99,0) -> 0 | F99: =ROUND(E99*0.195,0) -> 0 | G99: =E99+F99 -> 0
A100: 14 | E100: =ROUND((D100/21)*C100,0) -> 0 | F100: =ROUND(E100*0.195,0) -> 0 | G100: =E100+F100 -> 0
A101: 15 | E101: =ROUND((D101/21)*C101,0) -> 0 | F101: =ROUND(E101*0.195,0) -> 0 | G101: =E101+F101 -> 0
B102: RAZEM | C102: =SUM(C87:C101) -> 15 | D102: =SUM(D87:D101) -> 25682.5 | E102: =SUM(E87:E101) -> 2763 | F102: =SUM(F87:F101) -> 539 | G102: =SUM(G87:G101) -> 3302
C104: wprowadź wartość rezerwy z zeszłego (starego) miesiąca | D104: -127 | F104: =ROUND(D104*0.195,0) -> -25 | G104: =D104+F104 -> -152
F105: Rezerwa z nowego miesiąca | G105: =G102 -> 3302
F106: Kwota do raportu DOS+ | G106: =G105-G104 -> 3454

Sheet CALCULATOR
B1: KAWIARNIA | C1: =IFERROR(VLOOKUP(F1,DANE!$AA$3:$AB$100,2,FALSE),"") -> SBX Warszawa Janki | F1: 108120 | H1: MANAGER TARGET | I1: Imię i Nazwisko | J1: Stanowisko | K1: Wymiar etatu | L1: Stawka brutto | M1: Planowany czas pracy | N1: Zwolnienie lekarskie | O1: Urlop | P1: Bonus Plan | Q1: ON | R1: MANAGER ESTIMATION | S1: Rzeczywisty czas pracy | T1: Zwolnienie lekarskie | U1: Urlop | V1: Bonus Estimation | W1: Store cost | X1: Etat | Y1: VARIABLES | AA1: MANAGER - TARGET | AB1: Basic salary manager | AC1: Bonus Plan | AD1: Social insurance | AE1: FGŚP + Fundusz Pracy | AF1: Equivalent | AG1: PFRON | AH1: Comp&Ben | AI1: JPA Accrual | AJ1: COL TOTAL | AL1: MANAGER - SICK LEAVE | AM1: Basic salary manager | AN1: Social insurance: | AO1: COL TOTAL | AP1: Sick Leave Salary | AX1: MANAGER - ESTIMATION | AY1: Basic salary manager | AZ1: Bonus Plan | BA1: Social insurance | BB1: FGŚP + Fundusz Pracy | BC1: Equivalent | BD1: PFRON | BE1: Comp&Ben | BF1: JPA Accrual | BG1: COL TOTAL | BI1: MANAGER - SICK LEAVE | BJ1: Basic salary manager | BK1: Social insurance: | BL1: COL TOTAL | BM1: Sick Leave Salary
I3: Dawid Szeluga | J3: SM | K3: 1 | L3: 7200 | M3: 176 | S3: 176 | W3: 1 | X3: =IFERROR(IF(Q3="Tak",K3*$C$8/8*7*W3,K3*$C$8),"") -> 176 | Y3: SOCIAL INSURANCE | AB3: =K3*L3*W3-AM3 -> 7200 | AC3: =P3 -> 0 | AD3: =(AB3+AC3+AH3+AI3)*$Y$4-AN3 -> 1331.8831 | AE3: =(AB3+AC3+AH3+AI3)*$Y$6 -> 200.6085 | AF3: =(IFERROR(VLOOKUP(J3,DANE!$B$3:$H$7,5,FALSE),"0")*K3)*W3 -> 300 | AG3: =K3*$Y$13*W3 -> 200 | AH3: =IFERROR(VLOOKUP(J3,DANE!$B$2:$I$7,7,FALSE),"0")*W3 -> 300 | AI3: =IF(J3="SM","367","0")*K3*W3 -> 367 | AJ3: =SUM(AB3:AI3) -> 9899.4916 | AM3: =L3/$Y$18*N3*$AP$3 -> 0 | AN3: =AM3*$Y$4*$AP$3 -> 0 | AO3: =SUM(AM3:AN3) -> 0 | AP3: 0.2 | AY3: =K3*L3*W3-BJ3 -> 7200 | AZ3: =V3 -> 0 | BA3: =(AY3+AZ3+BE3+BF3)*$Y$4-BK3 -> 1331.8831 | BB3: =(AY3+AZ3+BE3+BF3)*$Y$6 -> 200.6085 | BC3: =IFERROR(VLOOKUP(J3,DANE!$B$3:$H$7,5,FALSE),"0")*K3*W3 -> 300 | BD3: =K3*$Y$13*W3 -> 200 | BE3: =IFERROR(VLOOKUP(J3,DANE!$B$2:$I$7,7,FALSE),"0")*W3 -> 300 | BF3: =IF(J3="SM","367","0")*K3*W3 -> 367 | BG3: =SUM(AY3:BF3) -> 9899.4916 | BJ3: =L3/$Y$18*T3*$BM$3 -> 0 | BK3: =BJ3*$Y$4*$BM$3 -> 0 | BL3: =SUM(BJ3:BK3) -> 0 | BM3: 0.2
B4: COL | C4: TARGET | D4: AOP | E4: ESTIMATION | F4: P&L | I4: Dawid Apel | J4: ASM | K4: 1 | L4: 6300 | M4: 176 | S4: 176 | W4: 1 | X4: =IFERROR(IF(Q4="Tak",K4*$C$8/8*7*W4,K4*$C$8),"") -> 176 | Y4: =DANE!E3 -> 0.1693 | AB4: =K4*L4*W4-AM4 -> 6300 | AC4: =P4 -> 0 | AD4: =(AB4+AC4+AH4+AI4)*$Y$4-AN4 -> 1108.915 | AE4: =(AB4+AC4+AH4+AI4)*$Y$6 -> 167.025 | AF4: =(IFERROR(VLOOKUP(J4,DANE!$B$3:$H$7,5,FALSE),"0")*K4)*W4 -> 300 | AG4: =K4*$Y$13*W4 -> 200 | AH4: =IFERROR(VLOOKUP(J4,DANE!$B$2:$I$7,7,FALSE),"0")*W4 -> 250 | AI4: =IF(J4="SM","367","0")*K4*W4 -> 0 | AJ4: =SUM(AB4:AI4) -> 8325.94 | AM4: =L4/$Y$18*N4*$AP$3 -> 0 | AN4: =AM4*$Y$4*$AP$3 -> 0 | AO4: =SUM(AM4:AN4) -> 0 | AP4: GROSS BASE SALARY/ETAT* SICK LEAVE HOURS *20% I o 20% zmniejsza się Basic Salary Manager i Social Insurance w Manager - Target | AY4: =K4*L4*W4-BJ4 -> 6300 | AZ4: =V4 -> 0 | BA4: =(AY4+AZ4+BE4+BF4)*$Y$4-BK4 -> 1108.915 | BB4: =(AY4+AZ4+BE4+BF4)*$Y$6 -> 167.025 | BC4: =IFERROR(VLOOKUP(J4,DANE!$B$3:$H$7,5,FALSE),"0")*K4*W4 -> 300 | BD4: =K4*$Y$13*W4 -> 200 | BE4: =IFERROR(VLOOKUP(J4,DANE!$B$2:$I$7,7,FALSE),"0")*W4 -> 250 | BF4: =IF(J4="SM","367","0")*K4*W4 -> 0 | BG4: =SUM(AY4:BF4) -> 8325.94 | BJ4: =L4/$Y$18*T4*$BM$3 -> 0 | BK4: =BJ4*$Y$4*$BM$3 -> 0 | BL4: =SUM(BJ4:BK4) -> 0 | BM4: GROSS BASE SALARY/ETAT* SICK LEAVE HOURS *20% I o 20% zmniejsza się Basic Salary Manager i Social Insurance w Manager - Target
B5: MONTH | C5: WRZESIEŃ | I5: Zuzanna Makowska | J5: SSV-PM | K5: 0.75 | L5: 3510 | M5: 96 | O5: 5 | S5: 96 | U5: 5 | W5: 1 | X5: =IFERROR(IF(Q5="Tak",K5*$C$8/8*7*W5,K5*$C$8),"") -> 132 | Y5: FGŚP + Fundusz Pracy | AB5: =K5*L5*W5-AM5 -> 2632.5 | AC5: =P5 -> 0 | AD5: =(AB5+AC5+AH5+AI5)*$Y$4-AN5 -> 479.54225 | AE5: =(AB5+AC5+AH5+AI5)*$Y$6 -> 72.22875 | AF5: =(IFERROR(VLOOKUP(J5,DANE!$B$3:$H$7,5,FALSE),"0")*K5)*W5 -> 262.5 | AG5: =K5*$Y$13*W5 -> 150 | AH5: =IFERROR(VLOOKUP(J5,DANE!$B$2:$I$7,7,FALSE),"0")*W5 -> 200 | AI5: =IF(J5="SM","367","0")*K5*W5 -> 0 | AJ5: =SUM(AB5:AI5) -> 3796.771 | AM5: =L5/$Y$18*N5*$AP$3 -> 0 | AN5: =AM5*$Y$4*$AP$3 -> 0 | AO5: =SUM(AM5:AN5) -> 0 | AY5: =K5*L5*W5-BJ5 -> 2632.5 | AZ5: =V5 -> 0 | BA5: =(AY5+AZ5+BE5+BF5)*$Y$4-BK5 -> 479.54225 | BB5: =(AY5+AZ5+BE5+BF5)*$Y$6 -> 72.22875 | BC5: =IFERROR(VLOOKUP(J5,DANE!$B$3:$H$7,5,FALSE),"0")*K5*W5 -> 262.5 | BD5: =K5*$Y$13*W5 -> 150 | BE5: =IFERROR(VLOOKUP(J5,DANE!$B$2:$I$7,7,FALSE),"0")*W5 -> 200 | BF5: =IF(J5="SM","367","0")*K5*W5 -> 0 | BG5: =SUM(AY5:BF5) -> 3796.771 | BJ5: =L5/$Y$18*T5*$BM$3 -> 0 | BK5: =BJ5*$Y$4*$BM$3 -> 0 | BL5: =SUM(BJ5:BK5) -> 0
I6: Weronika Bieńkowska | J6: SSV | K6: 0.5 | L6: 5600 | M6: 88 | O6: 3 | S6: 39 | T6: 4 | U6: 3 | W6: 1 | X6: =IFERROR(IF(Q6="Tak",K6*$C$8/8*7*W6,K6*$C$8),"") -> 88 | Y6: 0.0255 | AB6: =K6*L6*W6-AM6 -> 2800 | AC6: =P6 -> 0 | AD6: =(AB6+AC6+AH6+AI6)*$Y$4-AN6 -> 507.9 | AE6: =(AB6+AC6+AH6+AI6)*$Y$6 -> 76.5 | AF6: =(IFERROR(VLOOKUP(J6,DANE!$B$3:$H$7,5,FALSE),"0")*K6)*W6 -> 175 | AG6: =K6*$Y$13*W6 -> 100 | AH6: =IFERROR(VLOOKUP(J6,DANE!$B$2:$I$7,7,FALSE),"0")*W6 -> 200 | AI6: =IF(J6="SM","367","0")*K6*W6 -> 0 | AJ6: =SUM(AB6:AI6) -> 3859.4 | AM6: =L6/$Y$18*N6*$AP$3 -> 0 | AN6: =AM6*$Y$4*$AP$3 -> 0 | AO6: =SUM(AM6:AN6) -> 0 | AY6: =K6*L6*W6-BJ6 -> 2774.5455 | AZ6: =V6 -> 0 | BA6: =(AY6+AZ6+BE6+BF6)*$Y$4-BK6 -> 502.72865 | BB6: =(AY6+AZ6+BE6+BF6)*$Y$6 -> 75.850909 | BC6: =IFERROR(VLOOKUP(J6,DANE!$B$3:$H$7,5,FALSE),"0")*K6*W6 -> 175 | BD6: =K6*$Y$13*W6 -> 100 | BE6: =IFERROR(VLOOKUP(J6,DANE!$B$2:$I$7,7,FALSE),"0")*W6 -> 200 | BF6: =IF(J6="SM","367","0")*K6*W6 -> 0 | BG6: =SUM(AY6:BF6) -> 3828.125 | BJ6: =L6/$Y$18*T6*$BM$3 -> 25.454545 | BK6: =BJ6*$Y$4*$BM$3 -> 0.86189091 | BL6: =SUM(BJ6:BK6) -> 26.316436
B7: OPEN DAYS STORE | I7: Nikola Studzińska | J7: SSV | K7: 0.5 | L7: 2300 | M7: 56 | O7: 4 | S7: 60 | U7: 4 | W7: 1 | X7: =IFERROR(IF(Q7="Tak",K7*$C$8/8*7*W7,K7*$C$8),"") -> 88 | AB7: =K7*L7*W7-AM7 -> 1150 | AC7: =P7 -> 0 | AD7: =(AB7+AC7+AH7+AI7)*$Y$4-AN7 -> 228.555 | AE7: =(AB7+AC7+AH7+AI7)*$Y$6 -> 34.425 | AF7: =(IFERROR(VLOOKUP(J7,DANE!$B$3:$H$7,5,FALSE),"0")*K7)*W7 -> 175 | AG7: =K7*$Y$13*W7 -> 100 | AH7: =IFERROR(VLOOKUP(J7,DANE!$B$2:$I$7,7,FALSE),"0")*W7 -> 200 | AI7: =IF(J7="SM","367","0")*K7*W7 -> 0 | AJ7: =SUM(AB7:AI7) -> 1887.98 | AM7: =L7/$Y$18*N7*$AP$3 -> 0 | AN7: =AM7*$Y$4*$AP$3 -> 0 | AO7: =SUM(AM7:AN7) -> 0 | AY7: =K7*L7*W7-BJ7 -> 1150 | AZ7: =V7 -> 0 | BA7: =(AY7+AZ7+BE7+BF7)*$Y$4-BK7 -> 228.555 | BB7: =(AY7+AZ7+BE7+BF7)*$Y$6 -> 34.425 | BC7: =IFERROR(VLOOKUP(J7,DANE!$B$3:$H$7,5,FALSE),"0")*K7*W7 -> 175 | BD7: =K7*$Y$13*W7 -> 100 | BE7: =IFERROR(VLOOKUP(J7,DANE!$B$2:$I$7,7,FALSE),"0")*W7 -> 200 | BF7: =IF(J7="SM","367","0")*K7*W7 -> 0 | BG7: =SUM(AY7:BF7) -> 1887.98 | BJ7: =L7/$Y$18*T7*$BM$3 -> 0 | BK7: =BJ7*$Y$4*$BM$3 -> 0 | BL7: =SUM(BJ7:BK7) -> 0
B8: FULL CONTRACT IS (IN HOURS) | C8: =IFERROR(VLOOKUP(C5,DANE!$J$3:$L$14,3,FALSE),"") -> 176 | I8: Kamil Kamiński | J8: SSV | K8: 1 | L8: 5600 | M8: 128 | O8: 6 | S8: 128 | U8: 6 | V8: 300 | W8: 1 | X8: =IFERROR(IF(Q8="Tak",K8*$C$8/8*7*W8,K8*$C$8),"") -> 176 | AB8: =K8*L8*W8-AM8 -> 5600 | AC8: =P8 -> 0 | AD8: =(AB8+AC8+AH8+AI8)*$Y$4-AN8 -> 981.94 | AE8: =(AB8+AC8+AH8+AI8)*$Y$6 -> 147.9 | AF8: =(IFERROR(VLOOKUP(J8,DANE!$B$3:$H$7,5,FALSE),"0")*K8)*W8 -> 350 | AG8: =K8*$Y$13*W8 -> 200 | AH8: =IFERROR(VLOOKUP(J8,DANE!$B$2:$I$7,7,FALSE),"0")*W8 -> 200 | AI8: =IF(J8="SM","367","0")*K8*W8 -> 0 | AJ8: =SUM(AB8:AI8) -> 7479.84 | AM8: =L8/$Y$18*N8*$AP$3 -> 0 | AN8: =AM8*$Y$4*$AP$3 -> 0 | AO8: =SUM(AM8:AN8) -> 0 | AY8: =K8*L8*W8-BJ8 -> 5600 | AZ8: =V8 -> 300 | BA8: =(AY8+AZ8+BE8+BF8)*$Y$4-BK8 -> 1032.73 | BB8: =(AY8+AZ8+BE8+BF8)*$Y$6 -> 155.55 | BC8: =IFERROR(VLOOKUP(J8,DANE!$B$3:$H$7,5,FALSE),"0")*K8*W8 -> 350 | BD8: =K8*$Y$13*W8 -> 200 | BE8: =IFERROR(VLOOKUP(J8,DANE!$B$2:$I$7,7,FALSE),"0")*W8 -> 200 | BF8: =IF(J8="SM","367","0")*K8*W8 -> 0 | BG8: =SUM(AY8:BF8) -> 7838.28 | BJ8: =L8/$Y$18*T8*$BM$3 -> 0 | BK8: =BJ8*$Y$4*$BM$3 -> 0 | BL8: =SUM(BJ8:BK8) -> 0
B9: SALES | C9: 310000 | D9: =IFERROR(VLOOKUP($B9,AOP!$A$3:$Z$100,VLOOKUP(CALCULATOR!$C$5,DANE!$B$17:$C$28,2,FALSE),FALSE),"") | E9: 280000 | W9: 1 | X9: =IFERROR(IF(Q9="Tak",K9*$C$8/8*7*W9,K9*$C$8),"") -> 0 | AB9: =K9*L9*W9-AM9 -> 0 | AC9: =P9 -> 0 | AD9: =(AB9+AC9+AH9+AI9)*$Y$4-AN9 -> 0 | AE9: =(AB9+AC9+AH9+AI9)*$Y$6 -> 0 | AF9: =(IFERROR(VLOOKUP(J9,DANE!$B$3:$H$7,5,FALSE),"0")*K9)*W9 -> 0 | AG9: =K9*$Y$13*W9 -> 0 | AH9: =IFERROR(VLOOKUP(J9,DANE!$B$2:$I$7,7,FALSE),"0")*W9 -> 0 | AI9: =IF(J9="SM","367","0")*K9*W9 -> 0 | AJ9: =SUM(AB9:AI9) -> 0 | AM9: =L9/$Y$18*N9*$AP$3 -> 0 | AN9: =AM9*$Y$4*$AP$3 -> 0 | AO9: =SUM(AM9:AN9) -> 0 | AY9: =K9*L9*W9-BJ9 -> 0 | AZ9: =V9 -> 0 | BA9: =(AY9+AZ9+BE9+BF9)*$Y$4-BK9 -> 0 | BB9: =(AY9+AZ9+BE9+BF9)*$Y$6 -> 0 | BC9: =IFERROR(VLOOKUP(J9,DANE!$B$3:$H$7,5,FALSE),"0")*K9*W9 -> 0 | BD9: =K9*$Y$13*W9 -> 0 | BE9: =IFERROR(VLOOKUP(J9,DANE!$B$2:$I$7,7,FALSE),"0")*W9 -> 0 | BF9: =IF(J9="SM","367","0")*K9*W9 -> 0 | BG9: =SUM(AY9:BF9) -> 0 | BJ9: =L9/$Y$18*T9*$BM$3 -> 0 | BK9: =BJ9*$Y$4*$BM$3 -> 0 | BL9: =SUM(BJ9:BK9) -> 0
W10: 1 | X10: =IFERROR(IF(Q10="Tak",K10*$C$8/8*7*W10,K10*$C$8),"") -> 0 | AB10: =K10*L10*W10-AM10 -> 0 | AC10: =P10 -> 0 | AD10: =(AB10+AC10+AH10+AI10)*$Y$4-AN10 -> 0 | AE10: =(AB10+AC10+AH10+AI10)*$Y$6 -> 0 | AF10: =(IFERROR(VLOOKUP(J10,DANE!$B$3:$H$7,5,FALSE),"0")*K10)*W10 -> 0 | AG10: =K10*$Y$13*W10 -> 0 | AH10: =IFERROR(VLOOKUP(J10,DANE!$B$2:$I$7,7,FALSE),"0")*W10 -> 0 | AI10: =IF(J10="SM","367","0")*K10*W10 -> 0 | AJ10: =SUM(AB10:AI10) -> 0 | AM10: =L10/$Y$18*N10*$AP$3 -> 0 | AN10: =AM10*$Y$4*$AP$3 -> 0 | AO10: =SUM(AM10:AN10) -> 0 | AY10: =K10*L10*W10-BJ10 -> 0 | AZ10: =V10 -> 0 | BA10: =(AY10+AZ10+BE10+BF10)*$Y$4-BK10 -> 0 | BB10: =(AY10+AZ10+BE10+BF10)*$Y$6 -> 0 | BC10: =IFERROR(VLOOKUP(J10,DANE!$B$3:$H$7,5,FALSE),"0")*K10*W10 -> 0 | BD10: =K10*$Y$13*W10 -> 0 | BE10: =IFERROR(VLOOKUP(J10,DANE!$B$2:$I$7,7,FALSE),"0")*W10 -> 0 | BF10: =IF(J10="SM","367","0")*K10*W10 -> 0 | BG10: =SUM(AY10:BF10) -> 0 | BJ10: =L10/$Y$18*T10*$BM$3 -> 0 | BK10: =BJ10*$Y$4*$BM$3 -> 0 | BL10: =SUM(BJ10:BK10) -> 0
B11: TRANSACTIONS | C11: 10900 | D11: =IFERROR(VLOOKUP(B11,AOP!$A$2:$Z$100,VLOOKUP(CALCULATOR!C5,DANE!B17:C28,2,FALSE),FALSE),"") | E11: 9700 | W11: 1 | X11: =IFERROR(IF(Q11="Tak",K11*$C$8/8*7*W11,K11*$C$8),"") -> 0 | AB11: =K11*L11*W11-AM11 -> 0 | AC11: =P11 -> 0 | AD11: =(AB11+AC11+AH11+AI11)*$Y$4-AN11 -> 0 | AE11: =(AB11+AC11+AH11+AI11)*$Y$6 -> 0 | AF11: =(IFERROR(VLOOKUP(J11,DANE!$B$3:$H$7,5,FALSE),"0")*K11)*W11 -> 0 | AG11: =K11*$Y$13*W11 -> 0 | AH11: =IFERROR(VLOOKUP(J11,DANE!$B$2:$I$7,7,FALSE),"0")*W11 -> 0 | AI11: =IF(J11="SM","367","0")*K11*W11 -> 0 | AJ11: =SUM(AB11:AI11) -> 0 | AM11: =L11/$Y$18*N11*$AP$3 -> 0 | AN11: =AM11*$Y$4*$AP$3 -> 0 | AO11: =SUM(AM11:AN11) -> 0 | AY11: =K11*L11*W11-BJ11 -> 0 | AZ11: =V11 -> 0 | BA11: =(AY11+AZ11+BE11+BF11)*$Y$4-BK11 -> 0 | BB11: =(AY11+AZ11+BE11+BF11)*$Y$6 -> 0 | BC11: =IFERROR(VLOOKUP(J11,DANE!$B$3:$H$7,5,FALSE),"0")*K11*W11 -> 0 | BD11: =K11*$Y$13*W11 -> 0 | BE11: =IFERROR(VLOOKUP(J11,DANE!$B$2:$I$7,7,FALSE),"0")*W11 -> 0 | BF11: =IF(J11="SM","367","0")*K11*W11 -> 0 | BG11: =SUM(AY11:BF11) -> 0 | BJ11: =L11/$Y$18*T11*$BM$3 -> 0 | BK11: =BJ11*$Y$4*$BM$3 -> 0 | BL11: =SUM(BJ11:BK11) -> 0
W12: 1 | X12: =IFERROR(IF(Q12="Tak",K12*$C$8/8*7*W12,K12*$C$8),"") -> 0 | Y12: PFRON | AB12: =K12*L12*W12-AM12 -> 0 | AC12: =P12 -> 0 | AD12: =(AB12+AC12+AH12+AI12)*$Y$4-AN12 -> 0 | AE12: =(AB12+AC12+AH12+AI12)*$Y$6 -> 0 | AF12: =(IFERROR(VLOOKUP(J12,DANE!$B$3:$H$7,5,FALSE),"0")*K12)*W12 -> 0 | AG12: =K12*$Y$13*W12 -> 0 | AH12: =IFERROR(VLOOKUP(J12,DANE!$B$2:$I$7,7,FALSE),"0")*W12 -> 0 | AI12: =IF(J12="SM","367","0")*K12*W12 -> 0 | AJ12: =SUM(AB12:AI12) -> 0 | AM12: =L12/$Y$18*N12*$AP$3 -> 0 | AN12: =AM12*$Y$4*$AP$3 -> 0 | AO12: =SUM(AM12:AN12) -> 0 | AY12: =K12*L12*W12-BJ12 -> 0 | AZ12: =V12 -> 0 | BA12: =(AY12+AZ12+BE12+BF12)*$Y$4-BK12 -> 0 | BB12: =(AY12+AZ12+BE12+BF12)*$Y$6 -> 0 | BC12: =IFERROR(VLOOKUP(J12,DANE!$B$3:$H$7,5,FALSE),"0")*K12*W12 -> 0 | BD12: =K12*$Y$13*W12 -> 0 | BE12: =IFERROR(VLOOKUP(J12,DANE!$B$2:$I$7,7,FALSE),"0")*W12 -> 0 | BF12: =IF(J12="SM","367","0")*K12*W12 -> 0 | BG12: =SUM(AY12:BF12) -> 0 | BJ12: =L12/$Y$18*T12*$BM$3 -> 0 | BK12: =BJ12*$Y$4*$BM$3 -> 0 | BL12: =SUM(BJ12:BK12) -> 0
B13: AVG DAILY OPENING HOURS | I13: Manager Maternity | Y13: 200 | AJ13: =SUM(AB13:AI13) -> 0 | BC13: =AF13 -> 0 | BE13: =AH13 -> 0 | BG13: =SUM(AY13:BF13) -> 0
B14: COL | C14: =C45 -> 78032.621 | D14: =D45 -> 0 | E14: =E45 -> 76149.551 | F14: =F45 -> 0 | I14: Manager Bench | W14: 1 | X14: =IFERROR(IF(Q14="Tak",K14*$C$8/8*7*W14,K14*$C$8),"") -> 0 | Y14: EQUIVALENT CREW | AB14: =K14*L14*W14-AM14 -> 0 | AC14: =P14 -> 0 | AD14: =(AB14+AC14+AH14+AI14)*$Y$4-AN14 -> 0 | AE14: =(AB14+AC14+AH14+AI14)*$Y$6 -> 0 | AF14: =(IFERROR(VLOOKUP(J14,DANE!$B$3:$H$7,5,FALSE),"0")*K14)*W14 -> 0 | AG14: =K14*$Y$13*W14 -> 0 | AH14: =(IFERROR(VLOOKUP(J14,DANE!$B$2:$I$7,7,FALSE),"0")*K14)*W14 -> 0 | AI14: =IF(J14="SM","367","0")*K14*W14 -> 0 | AJ14: =SUM(AB14:AI14) -> 0 | AM14: =L14/$Y$18*N14*$AP$3 -> 0 | AN14: =AM14*$Y$4*$AP$3 -> 0 | AO14: =SUM(AM14:AN14) -> 0 | AY14: =K14*L14*W14-BJ14 -> 0 | AZ14: =V14 -> 0 | BA14: =(AY14+AZ14+BE14+BF14)*$Y$4-BK14 -> 0 | BB14: =(AY14+AZ14+BE14+BF14)*$Y$6 -> 0 | BC14: =IFERROR(VLOOKUP(J14,DANE!$B$3:$H$7,5,FALSE),"0")*K14*W14 -> 0 | BD14: =K14*$Y$13*W14 -> 0 | BE14: =(IFERROR(VLOOKUP(J14,DANE!$B$2:$I$7,7,FALSE),"0")*K14)*W14 -> 0 | BF14: =IF(J14="SM","367","0")*K14*W14 -> 0 | BG14: =SUM(AY14:BF14) -> 0 | BJ14: =L14/$Y$18*T14*$BM$3 -> 0 | BK14: =BJ14*$Y$4*$BM$3 -> 0 | BL14: =SUM(BJ14:BK14) -> 0
I15: DM costs | P15: 685 | AC15: =P15 -> 685 | AD15: =P15*$Y$4 -> 115.9705 | AJ15: =SUM(AB15:AI15) -> 800.9705 | AZ15: =AC15 -> 685 | BA15: =AZ15*$Y$4 -> 115.9705 | BG15: =SUM(AY15:BF15) -> 800.9705
B16: COL% | C16: =IFERROR(C14/C9,"-") -> 0.25171813 | D16: =IFERROR(D14/D9,"-") -> - | E16: =IFERROR(E14/E9,"-") -> 0.27196268 | F16: =IFERROR(F14/F9,"-") -> - | I16: DOS+ accrual | Y16: =DANE!F9 -> 0.85 | AC16: =P16 -> 0 | AD16: =P16*$Y$4 -> 0 | AJ16: =SUM(AB16:AI16) -> 0 | AZ16: =AC16 -> 0 | BA16: =AZ16*$Y$4 -> 0 | BG16: =SUM(AY16:BF16) -> 0
I17: Holiday accrual | L17: ='Rezerwa urlopowa'!G106 -> 3454 | V17: 1819 | Y17: ETAT | AB17: =L17 -> 3454 | AJ17: =SUM(AB17:AI17) -> 3454 | AY17: =V17 -> 1819 | BG17: =SUM(AY17:BF17) -> 1819
B18: FIXED COL | C18: =IFERROR(C47+C48+C49+C56+C57+C60+C63+C62+C64+C66+C50+C51+C52,"") -> 44608.359 | D18: =IFERROR(D47+D48+D49+D56+D57+D60+D63+D62+D64+D66+D50+D51+D52,"") -> 0 | E18: =IFERROR(E47+E48+E49+E56+E57+E60+E63+E62+E64+E66+E50+E51+E52,"") -> 42892.713 | F18: =IFERROR(F47+F48+F49+F56+F57+F60+F63+F62+F64+F66+F50+F51+F52,"") -> 0 | H18: MANAGER TOTAL: | K18: =SUM(K3:K12) -> 4.75 | M18: =SUM(M3:M17) -> 720 | N18: =SUM(N3:N17) -> 0 | O18: =SUM(O3:O17) -> 18 | P18: =SUM(P3:P17)-P19 -> 685 | S18: =SUM(S3:S17) -> 675 | T18: =SUM(T3:T17) -> 4 | U18: =SUM(U3:U17) -> 18 | V18: =SUM(V3:V16)-V19 -> 0 | Y18: =VLOOKUP(CALCULATOR!$C$5,DANE!J3:L14,3,FALSE) -> 176 | AB18: =SUM(AB3:AB17)-AD17 -> 29136.5 | AC18: =SUM(AC3:AC17)-AC19 -> 685 | AD18: =SUM(AD3:AD17) -> 4754.7059 | AE18: =SUM(AE3:AE17) -> 698.68725 | AF18: =SUM(AF3:AF17) -> 1562.5 | AG18: =SUM(AG3:AG17) -> 950 | AH18: =SUM(AH3:AH17) -> 1350 | AI18: =SUM(AI3:AI17) -> 367 | AJ18: =SUM(AJ3:AJ17) -> 39504.393 | AM18: =SUM(AM3:AM17) -> 0 | AN18: =SUM(AN3:AN17) -> 0 | AO18: =SUM(AO3:AO17) -> 0 | AY18: =SUM(AY3:AY17)-BA17 -> 27476.045 | AZ18: =SUM(AZ3:AZ17)-AZ19 -> 685 | BA18: =SUM(BA3:BA17) -> 4800.3245 | BB18: =SUM(BB3:BB17) -> 705.68816 | BC18: =SUM(BC3:BC17) -> 1562.5 | BD18: =SUM(BD3:BD17) -> 950 | BE18: =SUM(BE3:BE17) -> 1350 | BF18: =SUM(BF3:BF17) -> 367 | BG18: =SUM(BG3:BG17) -> 38196.558 | BJ18: =SUM(BJ3:BJ17) -> 25.454545 | BK18: =SUM(BK3:BK17) -> 0.86189091 | BL18: =SUM(BL3:BL17) -> 26.316436
P19: =SUMIF($J$3:$J$12,"SSV",P3:P12) -> 0 | V19: =SUMIF($J$3:$J$12,"SSV",V3:V12) -> 300 | AC19: =SUMIF($J$3:$J$12,"SSV",AC3:AC12) -> 0 | AZ19: =SUMIF($J$3:$J$12,"SSV",AZ3:AZ12) -> 300
H20: UMOWA O PRACĘ - TARGET | I20: Imię i Nazwisko | J20: Stanowisko | K20: Wymiar etatu | L20: Stawka brutto | M20: Planowany czas pracy | N20: Zwolnienie lekarskie | O20: Urlop | P20: Etat | Q20: ON | R20: UMOWA O PRACĘ - ESTIMATION | S20: Rzeczywisty czas pracy | T20: Zwolnienie lekarskie | U20: Urlop | V20: Bonus | W20: ALERT: | Y20: Hourly Job - Barista | AA20: UMOWA O PRACĘ - TARGET | AB20: Basic salary crew | AD20: Social insurance: | AE20: FGŚP + Fundusz Pracy | AF20: Equivalent | AG20: PFRON: | AJ20: COL TOTAL | AL20: UMOWA O PRACĘ - PLAN - SICK LEAVE | AM20: Basic salary crew | AN20: Social insurance: | AO20: COL TOTAL | AP20: Sick Leave Salary | AR20: UMOWA O PRACĘ - HOLIDAY - TARGET | AS20: Basic salary crew | AT20: Social insurance: | AU20: Equivalent | AV20: COL TOTAL | AX20: UMOWA O PRACĘ - ESTIMATION | AY20: Basic salary crew | BA20: Social insurance: | BB20: FGŚP + Fundusz Pracy | BC20: Equivalent | BD20: PFRON: | BG20: COL TOTAL | BI20: UMOWA O PRACĘ - ESTIMATION - SICK LEAVE | BJ20: Basic salary crew | BK20: Social insurance: | BL20: COL TOTAL | BM20: Sick Leave Salary | BO20: UMOWA O PRACĘ - HOLIDAY - ESTIMATION | BP20: Basic salary crew | BQ20: Social insurance: | BR20: Equivalent | BS20: COL TOTAL
B21: MANAGER WORKING HOURS | C21: =M18 -> 720 | E21: =S18 -> 675
B22: CREW WORKING HOURS | C22: =IFERROR(M41+M66,"") -> 1040 | E22: =S41+S66 -> 1038.5 | I22: Hanna Domachowska | J22: BT | K22: 0.5 | L22: 31.4 | M22: 88 | P22: =IFERROR(IF(Q22="tak",$C$8/8*7*K22,K22*$C$8),"") -> 88 | S22: 85 | W22: =IF(AND(SUM(M22:O22)<P22,(SUM(M22:O22)>0)),"TARGET: NIEDOGODZINY",IF(SUM(M22:O22)>P22,"TARGET: NADGODZINY",IF(AND(SUM(S22:U22)<P22,(SUM(S22:U22)>0)),"ESTIMATION: NIEDOGODZINY",IF(SUM(S22:U22)>P22,"ESTIMATION: NADGODZINY","-")))) -> ESTIMATION: NIEDOGODZINY | Y22: =IF(OR(J22="KP",J22="BT",J22="LOBBY",J22="B"),(L22*1.1948)+0.7,"-") -> 38.21672 | AB22: =IF(L22<VLOOKUP($C$5,DANE!$J$3:$N$14,4,FALSE),VLOOKUP($C$5,DANE!$J$3:$N$14,4,FALSE)*M22,L22*M22) -> 2763.2 | AD22: =AB22*$Y$4 -> 467.80976 | AE22: =AB22*$Y$6 -> 70.4616 | AF22: =M22*$Y$16 -> 74.8 | AG22: =K22*$Y$13 -> 100 | AJ22: =SUM(AB22:AG22) -> 3476.2714 | AM22: =N22*IF(L22<VLOOKUP($C$5,DANE!$J$3:$N$14,4,FALSE),VLOOKUP($C$5,DANE!$J$3:$N$14,4,FALSE),L22)*$AP$22 -> 0 | AN22: =AM22*$Y$4*$AP$22 -> 0 | AO22: =SUM(AM22:AN22) -> 0 | AP22: 0.8 | AS22: =O22*IF(L22<VLOOKUP($C$5,DANE!$J$3:$N$14,4,FALSE),VLOOKUP($C$5,DANE!$J$3:$N$14,4,FALSE),L22) -> 0 | AT22: =AS22*$Y$4 -> 0 | AU22: =O22*$Y$16 -> 0 | AV22: =SUM(AS22:AT22) -> 0 | AY22: =IF(L22<VLOOKUP($C$5,DANE!$J$3:$N$14,4,FALSE),VLOOKUP($C$5,DANE!$J$3:$N$14,4,FALSE)*S22,L22*S22) -> 2669 | BA22: =AY22*$Y$4 -> 451.8617 | BB22: =AY22*$Y$6 -> 68.0595 | BC22: =S22*$Y$16 -> 72.25 | BD22: =K22*$Y$13 -> 100 | BG22: =SUM(AY22:BD22) -> 3361.1712 | BJ22: =T22*IF(L22<VLOOKUP($C$5,DANE!$J$3:$N$14,4,FALSE),VLOOKUP($C$5,DANE!$J$3:$N$14,4,FALSE),L22)*$BM$22 -> 0 | BK22: =BJ22*$Y$4*$BM$22 -> 0 | BL22: =SUM(BJ22:BK22) -> 0 | BM22: 0.8 | BP22: =U22*IF(L22<VLOOKUP($C$5,DANE!$J$3:$N$14,4,FALSE),VLOOKUP($C$5,DANE!$J$3:$N$14,4,FALSE),L22) -> 0 | BQ22: =BP22*$Y$4 -> 0 | BR22: =U22*$Y$16 -> 0 | BS22: =SUM(BP22:BQ22) -> 0
B23: TPLH (Total) | C23: =IFERROR(C11/C36,"-") -> 6.1931818 | E23: =IFERROR(E11/E36,"-") -> 5.6609279 | F23: =IFERROR(F11/F36,"-") -> - | I23: Gabriela Znojek | J23: B | K23: 0.75 | L23: 30.75 | M23: 132 | P23: =IFERROR(IF(Q23="tak",$C$8/8*7*K23,K23*$C$8),"") -> 132 | S23: 120 | W23: =IF(AND(SUM(M23:O23)<P23,(SUM(M23:O23)>0)),"TARGET: NIEDOGODZINY",IF(SUM(M23:O23)>P23,"TARGET: NADGODZINY",IF(AND(SUM(S23:U23)<P23,(SUM(S23:U23)>0)),"ESTIMATION: NIEDOGODZINY",IF(SUM(S23:U23)>P23,"ESTIMATION: NADGODZINY","-")))) -> ESTIMATION: NIEDOGODZINY | Y23: =IF(OR(J23="KP",J23="BT",J23="LOBBY",J23="B"),(L23*1.1948)+0.7,"-") -> 37.4401 | AB23: =IF(L23<VLOOKUP($C$5,DANE!$J$3:$N$14,4,FALSE),VLOOKUP($C$5,DANE!$J$3:$N$14,4,FALSE)*M23,L23*M23) -> 4059 | AD23: =AB23*$Y$4 -> 687.1887 | AE23: =AB23*$Y$6 -> 103.5045 | AF23: =M23*$Y$16 -> 112.2 | AG23: =K23*$Y$13 -> 150 | AJ23: =SUM(AB23:AG23) -> 5111.8932 | AM23: =N23*IF(L23<VLOOKUP($C$5,DANE!$J$3:$N$14,4,FALSE),VLOOKUP($C$5,DANE!$J$3:$N$14,4,FALSE),L23)*$AP$22 -> 0 | AN23: =AM23*$Y$4*$AP$22 -> 0 | AO23: =SUM(AM23:AN23) -> 0 | AS23: =O23*IF(L23<VLOOKUP($C$5,DANE!$J$3:$N$14,4,FALSE),VLOOKUP($C$5,DANE!$J$3:$N$14,4,FALSE),L23) -> 0 | AT23: =AS23*$Y$4 -> 0 | AU23: =O23*$Y$16 -> 0 | AV23: =SUM(AS23:AT23) -> 0 | AY23: =IF(L23<VLOOKUP($C$5,DANE!$J$3:$N$14,4,FALSE),VLOOKUP($C$5,DANE!$J$3:$N$14,4,FALSE)*S23,L23*S23) -> 3690 | BA23: =AY23*$Y$4 -> 624.717 | BB23: =AY23*$Y$6 -> 94.095 | BC23: =S23*$Y$16 -> 102 | BD23: =K23*$Y$13 -> 150 | BG23: =SUM(AY23:BD23) -> 4660.812 | BJ23: =T23*IF(L23<VLOOKUP($C$5,DANE!$J$3:$N$14,4,FALSE),VLOOKUP($C$5,DANE!$J$3:$N$14,4,FALSE),L23)*$BM$22 -> 0 | BK23: =BJ23*$Y$4*$BM$22 -> 0 | BL23: =SUM(BJ23:BK23) -> 0 | BP23: =U23*IF(L23<VLOOKUP($C$5,DANE!$J$3:$N$14,4,FALSE),VLOOKUP($C$5,DANE!$J$3:$N$14,4,FALSE),L23) -> 0 | BQ23: =BP23*$Y$4 -> 0 | BR23: =U23*$Y$16 -> 0 | BS23: =SUM(BP23:BQ23) -> 0
B24: TPLH (Coverage) | C24: =IFERROR(C11/(C36-C27-C30),"-") -> 6.4688427 | E24: =IFERROR(E11/(E36-E27-E30),"-") -> 5.6609279 | F24: =IFERROR(F11/(F36-F27-F30),"-") -> - | P24: =IFERROR(IF(Q24="tak",$C$8/8*7*K24,K24*$C$8),"") -> 0 | W24: =IF(AND(SUM(M24:O24)<P24,(SUM(M24:O24)>0)),"TARGET: NIEDOGODZINY",IF(SUM(M24:O24)>P24,"TARGET: NADGODZINY",IF(AND(SUM(S24:U24)<P24,(SUM(S24:U24)>0)),"ESTIMATION: NIEDOGODZINY",IF(SUM(S24:U24)>P24,"ESTIMATION: NADGODZINY","-")))) -> - | Y24: =IF(OR(J24="KP",J24="BT",J24="LOBBY",J24="B"),(L24*1.1948)+0.7,"-") -> - | AB24: =IF(L24<VLOOKUP($C$5,DANE!$J$3:$N$14,4,FALSE),VLOOKUP($C$5,DANE!$J$3:$N$14,4,FALSE)*M24,L24*M24) -> 0 | AD24: =AB24*$Y$4 -> 0 | AE24: =AB24*$Y$6 -> 0 | AF24: =M24*$Y$16 -> 0 | AG24: =K24*$Y$13 -> 0 | AJ24: =SUM(AB24:AG24) -> 0 | AM24: =N24*IF(L24<VLOOKUP($C$5,DANE!$J$3:$N$14,4,FALSE),VLOOKUP($C$5,DANE!$J$3:$N$14,4,FALSE),L24)*$AP$22 -> 0 | AN24: =AM24*$Y$4*$AP$22 -> 0 | AO24: =SUM(AM24:AN24) -> 0 | AS24: =O24*IF(L24<VLOOKUP($C$5,DANE!$J$3:$N$14,4,FALSE),VLOOKUP($C$5,DANE!$J$3:$N$14,4,FALSE),L24) -> 0 | AT24: =AS24*$Y$4 -> 0 | AU24: =O24*$Y$16 -> 0 | AV24: =SUM(AS24:AT24) -> 0 | AY24: =IF(L24<VLOOKUP($C$5,DANE!$J$3:$N$14,4,FALSE),VLOOKUP($C$5,DANE!$J$3:$N$14,4,FALSE)*S24,L24*S24) -> 0 | BA24: =AY24*$Y$4 -> 0 | BB24: =AY24*$Y$6 -> 0 | BC24: =S24*$Y$16 -> 0 | BD24: =K24*$Y$13 -> 0 | BG24: =SUM(AY24:BD24) -> 0 | BJ24: =T24*IF(L24<VLOOKUP($C$5,DANE!$J$3:$N$14,4,FALSE),VLOOKUP($C$5,DANE!$J$3:$N$14,4,FALSE),L24)*$BM$22 -> 0 | BK24: =BJ24*$Y$4*$BM$22 -> 0 | BL24: =SUM(BJ24:BK24) -> 0 | BP24: =U24*IF(L24<VLOOKUP($C$5,DANE!$J$3:$N$14,4,FALSE),VLOOKUP($C$5,DANE!$J$3:$N$14,4,FALSE),L24) -> 0 | BQ24: =BP24*$Y$4 -> 0 | BR24: =U24*$Y$16 -> 0 | BS24: =SUM(BP24:BQ24) -> 0
B25: TOTAL CONTRACTS | C25: =IFERROR(K18+K41+K66,"") -> 10.659091 | E25: =IFERROR(K18+K41+K66,"") -> 10.659091 | P25: =IFERROR(IF(Q25="tak",$C$8/8*7*K25,K25*$C$8),"") -> 0 | W25: =IF(AND(SUM(M25:O25)<P25,(SUM(M25:O25)>0)),"TARGET: NIEDOGODZINY",IF(SUM(M25:O25)>P25,"TARGET: NADGODZINY",IF(AND(SUM(S25:U25)<P25,(SUM(S25:U25)>0)),"ESTIMATION: NIEDOGODZINY",IF(SUM(S25:U25)>P25,"ESTIMATION: NADGODZINY","-")))) -> - | Y25: =IF(OR(J25="KP",J25="BT",J25="LOBBY",J25="B"),(L25*1.1948)+0.7,"-") -> - | AB25: =IF(L25<VLOOKUP($C$5,DANE!$J$3:$N$14,4,FALSE),VLOOKUP($C$5,DANE!$J$3:$N$14,4,FALSE)*M25,L25*M25) -> 0 | AD25: =AB25*$Y$4 -> 0 | AE25: =AB25*$Y$6 -> 0 | AF25: =M25*$Y$16 -> 0 | AG25: =K25*$Y$13 -> 0 | AJ25: =SUM(AB25:AG25) -> 0 | AM25: =N25*IF(L25<VLOOKUP($C$5,DANE!$J$3:$N$14,4,FALSE),VLOOKUP($C$5,DANE!$J$3:$N$14,4,FALSE),L25)*$AP$22 -> 0 | AN25: =AM25*$Y$4*$AP$22 -> 0 | AO25: =SUM(AM25:AN25) -> 0 | AS25: =O25*IF(L25<VLOOKUP($C$5,DANE!$J$3:$N$14,4,FALSE),VLOOKUP($C$5,DANE!$J$3:$N$14,4,FALSE),L25) -> 0 | AT25: =AS25*$Y$4 -> 0 | AU25: =O25*$Y$16 -> 0 | AV25: =SUM(AS25:AT25) -> 0 | AY25: =IF(L25<VLOOKUP($C$5,DANE!$J$3:$N$14,4,FALSE),VLOOKUP($C$5,DANE!$J$3:$N$14,4,FALSE)*S25,L25*S25) -> 0 | BA25: =AY25*$Y$4 -> 0 | BB25: =AY25*$Y$6 -> 0 | BC25: =S25*$Y$16 -> 0 | BD25: =K25*$Y$13 -> 0 | BG25: =SUM(AY25:BD25) -> 0 | BJ25: =T25*IF(L25<VLOOKUP($C$5,DANE!$J$3:$N$14,4,FALSE),VLOOKUP($C$5,DANE!$J$3:$N$14,4,FALSE),L25)*$BM$22 -> 0 | BK25: =BJ25*$Y$4*$BM$22 -> 0 | BL25: =SUM(BJ25:BK25) -> 0 | BP25: =U25*IF(L25<VLOOKUP($C$5,DANE!$J$3:$N$14,4,FALSE),VLOOKUP($C$5,DANE!$J$3:$N$14,4,FALSE),L25) -> 0 | BQ25: =BP25*$Y$4 -> 0 | BR25: =U25*$Y$16 -> 0 | BS25: =SUM(BP25:BQ25) -> 0
P26: =IFERROR(IF(Q26="tak",$C$8/8*7*K26,K26*$C$8),"") -> 0 | W26: =IF(AND(SUM(M26:O26)<P26,(SUM(M26:O26)>0)),"TARGET: NIEDOGODZINY",IF(SUM(M26:O26)>P26,"TARGET: NADGODZINY",IF(AND(SUM(S26:U26)<P26,(SUM(S26:U26)>0)),"ESTIMATION: NIEDOGODZINY",IF(SUM(S26:U26)>P26,"ESTIMATION: NADGODZINY","-")))) -> - | Y26: =IF(OR(J26="KP",J26="BT",J26="LOBBY",J26="B"),(L26*1.1948)+0.7,"-") -> - | AB26: =IF(L26<VLOOKUP($C$5,DANE!$J$3:$N$14,4,FALSE),VLOOKUP($C$5,DANE!$J$3:$N$14,4,FALSE)*M26,L26*M26) -> 0 | AD26: =AB26*$Y$4 -> 0 | AE26: =AB26*$Y$6 -> 0 | AF26: =M26*$Y$16 -> 0 | AG26: =K26*$Y$13 -> 0 | AJ26: =SUM(AB26:AG26) -> 0 | AM26: =N26*IF(L26<VLOOKUP($C$5,DANE!$J$3:$N$14,4,FALSE),VLOOKUP($C$5,DANE!$J$3:$N$14,4,FALSE),L26)*$AP$22 -> 0 | AN26: =AM26*$Y$4*$AP$22 -> 0 | AO26: =SUM(AM26:AN26) -> 0 | AS26: =O26*IF(L26<VLOOKUP($C$5,DANE!$J$3:$N$14,4,FALSE),VLOOKUP($C$5,DANE!$J$3:$N$14,4,FALSE),L26) -> 0 | AT26: =AS26*$Y$4 -> 0 | AU26: =O26*$Y$16 -> 0 | AV26: =SUM(AS26:AT26) -> 0 | AY26: =IF(L26<VLOOKUP($C$5,DANE!$J$3:$N$14,4,FALSE),VLOOKUP($C$5,DANE!$J$3:$N$14,4,FALSE)*S26,L26*S26) -> 0 | BA26: =AY26*$Y$4 -> 0 | BB26: =AY26*$Y$6 -> 0 | BC26: =S26*$Y$16 -> 0 | BD26: =K26*$Y$13 -> 0 | BG26: =SUM(AY26:BD26) -> 0 | BJ26: =T26*IF(L26<VLOOKUP($C$5,DANE!$J$3:$N$14,4,FALSE),VLOOKUP($C$5,DANE!$J$3:$N$14,4,FALSE),L26)*$BM$22 -> 0 | BK26: =BJ26*$Y$4*$BM$22 -> 0 | BL26: =SUM(BJ26:BK26) -> 0 | BP26: =U26*IF(L26<VLOOKUP($C$5,DANE!$J$3:$N$14,4,FALSE),VLOOKUP($C$5,DANE!$J$3:$N$14,4,FALSE),L26) -> 0 | BQ26: =BP26*$Y$4 -> 0 | BR26: =U26*$Y$16 -> 0 | BS26: =SUM(BP26:BQ26) -> 0
B27: NON COVERAGE | P27: =IFERROR(IF(Q27="tak",$C$8/8*7*K27,K27*$C$8),"") -> 0 | W27: =IF(AND(SUM(M27:O27)<P27,(SUM(M27:O27)>0)),"TARGET: NIEDOGODZINY",IF(SUM(M27:O27)>P27,"TARGET: NADGODZINY",IF(AND(SUM(S27:U27)<P27,(SUM(S27:U27)>0)),"ESTIMATION: NIEDOGODZINY",IF(SUM(S27:U27)>P27,"ESTIMATION: NADGODZINY","-")))) -> - | Y27: =IF(OR(J27="KP",J27="BT",J27="LOBBY",J27="B"),(L27*1.1948)+0.7,"-") -> - | AB27: =IF(L27<VLOOKUP($C$5,DANE!$J$3:$N$14,4,FALSE),VLOOKUP($C$5,DANE!$J$3:$N$14,4,FALSE)*M27,L27*M27) -> 0 | AD27: =AB27*$Y$4 -> 0 | AE27: =AB27*$Y$6 -> 0 | AF27: =M27*$Y$16 -> 0 | AG27: =K27*$Y$13 -> 0 | AJ27: =SUM(AB27:AG27) -> 0 | AM27: =N27*IF(L27<VLOOKUP($C$5,DANE!$J$3:$N$14,4,FALSE),VLOOKUP($C$5,DANE!$J$3:$N$14,4,FALSE),L27)*$AP$22 -> 0 | AN27: =AM27*$Y$4*$AP$22 -> 0 | AO27: =SUM(AM27:AN27) -> 0 | AS27: =O27*IF(L27<VLOOKUP($C$5,DANE!$J$3:$N$14,4,FALSE),VLOOKUP($C$5,DANE!$J$3:$N$14,4,FALSE),L27) -> 0 | AT27: =AS27*$Y$4 -> 0 | AU27: =O27*$Y$16 -> 0 | AV27: =SUM(AS27:AT27) -> 0 | AY27: =IF(L27<VLOOKUP($C$5,DANE!$J$3:$N$14,4,FALSE),VLOOKUP($C$5,DANE!$J$3:$N$14,4,FALSE)*S27,L27*S27) -> 0 | BA27: =AY27*$Y$4 -> 0 | BB27: =AY27*$Y$6 -> 0 | BC27: =S27*$Y$16 -> 0 | BD27: =K27*$Y$13 -> 0 | BG27: =SUM(AY27:BD27) -> 0 | BJ27: =T27*IF(L27<VLOOKUP($C$5,DANE!$J$3:$N$14,4,FALSE),VLOOKUP($C$5,DANE!$J$3:$N$14,4,FALSE),L27)*$BM$22 -> 0 | BK27: =BJ27*$Y$4*$BM$22 -> 0 | BL27: =SUM(BJ27:BK27) -> 0 | BP27: =U27*IF(L27<VLOOKUP($C$5,DANE!$J$3:$N$14,4,FALSE),VLOOKUP($C$5,DANE!$J$3:$N$14,4,FALSE),L27) -> 0 | BQ27: =BP27*$Y$4 -> 0 | BR27: =U27*$Y$16 -> 0 | BS27: =SUM(BP27:BQ27) -> 0
B28: HOLIDAY | C28: =O18+O41 -> 18 | E28: =U18+U41 -> 18 | P28: =IFERROR(IF(Q28="tak",$C$8/8*7*K28,K28*$C$8),"") -> 0 | W28: =IF(AND(SUM(M28:O28)<P28,(SUM(M28:O28)>0)),"TARGET: NIEDOGODZINY",IF(SUM(M28:O28)>P28,"TARGET: NADGODZINY",IF(AND(SUM(S28:U28)<P28,(SUM(S28:U28)>0)),"ESTIMATION: NIEDOGODZINY",IF(SUM(S28:U28)>P28,"ESTIMATION: NADGODZINY","-")))) -> - | Y28: =IF(OR(J28="KP",J28="BT",J28="LOBBY",J28="B"),(L28*1.1948)+0.7,"-") -> - | AB28: =IF(L28<VLOOKUP($C$5,DANE!$J$3:$N$14,4,FALSE),VLOOKUP($C$5,DANE!$J$3:$N$14,4,FALSE)*M28,L28*M28) -> 0 | AD28: =AB28*$Y$4 -> 0 | AE28: =AB28*$Y$6 -> 0 | AF28: =M28*$Y$16 -> 0 | AG28: =K28*$Y$13 -> 0 | AJ28: =SUM(AB28:AG28) -> 0 | AM28: =N28*IF(L28<VLOOKUP($C$5,DANE!$J$3:$N$14,4,FALSE),VLOOKUP($C$5,DANE!$J$3:$N$14,4,FALSE),L28)*$AP$22 -> 0 | AN28: =AM28*$Y$4*$AP$22 -> 0 | AO28: =SUM(AM28:AN28) -> 0 | AS28: =O28*IF(L28<VLOOKUP($C$5,DANE!$J$3:$N$14,4,FALSE),VLOOKUP($C$5,DANE!$J$3:$N$14,4,FALSE),L28) -> 0 | AT28: =AS28*$Y$4 -> 0 | AU28: =O28*$Y$16 -> 0 | AV28: =SUM(AS28:AT28) -> 0 | AY28: =IF(L28<VLOOKUP($C$5,DANE!$J$3:$N$14,4,FALSE),VLOOKUP($C$5,DANE!$J$3:$N$14,4,FALSE)*S28,L28*S28) -> 0 | BA28: =AY28*$Y$4 -> 0 | BB28: =AY28*$Y$6 -> 0 | BC28: =S28*$Y$16 -> 0 | BD28: =K28*$Y$13 -> 0 | BG28: =SUM(AY28:BD28) -> 0 | BJ28: =T28*IF(L28<VLOOKUP($C$5,DANE!$J$3:$N$14,4,FALSE),VLOOKUP($C$5,DANE!$J$3:$N$14,4,FALSE),L28)*$BM$22 -> 0 | BK28: =BJ28*$Y$4*$BM$22 -> 0 | BL28: =SUM(BJ28:BK28) -> 0 | BP28: =U28*IF(L28<VLOOKUP($C$5,DANE!$J$3:$N$14,4,FALSE),VLOOKUP($C$5,DANE!$J$3:$N$14,4,FALSE),L28) -> 0 | BQ28: =BP28*$Y$4 -> 0 | BR28: =U28*$Y$16 -> 0 | BS28: =SUM(BP28:BQ28) -> 0
B29: SICK LEAVE | C29: =N18+N41 -> 0 | E29: =T18+T41 -> 4 | P29: =IFERROR(IF(Q29="tak",$C$8/8*7*K29,K29*$C$8),"") -> 0 | W29: =IF(AND(SUM(M29:O29)<P29,(SUM(M29:O29)>0)),"TARGET: NIEDOGODZINY",IF(SUM(M29:O29)>P29,"TARGET: NADGODZINY",IF(AND(SUM(S29:U29)<P29,(SUM(S29:U29)>0)),"ESTIMATION: NIEDOGODZINY",IF(SUM(S29:U29)>P29,"ESTIMATION: NADGODZINY","-")))) -> - | Y29: =IF(OR(J29="KP",J29="BT",J29="LOBBY",J29="B"),(L29*1.1948)+0.7,"-") -> - | AB29: =IF(L29<VLOOKUP($C$5,DANE!$J$3:$N$14,4,FALSE),VLOOKUP($C$5,DANE!$J$3:$N$14,4,FALSE)*M29,L29*M29) -> 0 | AD29: =AB29*$Y$4 -> 0 | AE29: =AB29*$Y$6 -> 0 | AF29: =M29*$Y$16 -> 0 | AG29: =K29*$Y$13 -> 0 | AJ29: =SUM(AB29:AG29) -> 0 | AM29: =N29*IF(L29<VLOOKUP($C$5,DANE!$J$3:$N$14,4,FALSE),VLOOKUP($C$5,DANE!$J$3:$N$14,4,FALSE),L29)*$AP$22 -> 0 | AN29: =AM29*$Y$4*$AP$22 -> 0 | AO29: =SUM(AM29:AN29) -> 0 | AS29: =O29*IF(L29<VLOOKUP($C$5,DANE!$J$3:$N$14,4,FALSE),VLOOKUP($C$5,DANE!$J$3:$N$14,4,FALSE),L29) -> 0 | AT29: =AS29*$Y$4 -> 0 | AU29: =O29*$Y$16 -> 0 | AV29: =SUM(AS29:AT29) -> 0 | AY29: =IF(L29<VLOOKUP($C$5,DANE!$J$3:$N$14,4,FALSE),VLOOKUP($C$5,DANE!$J$3:$N$14,4,FALSE)*S29,L29*S29) -> 0 | BA29: =AY29*$Y$4 -> 0 | BB29: =AY29*$Y$6 -> 0 | BC29: =S29*$Y$16 -> 0 | BD29: =K29*$Y$13 -> 0 | BG29: =SUM(AY29:BD29) -> 0 | BJ29: =T29*IF(L29<VLOOKUP($C$5,DANE!$J$3:$N$14,4,FALSE),VLOOKUP($C$5,DANE!$J$3:$N$14,4,FALSE),L29)*$BM$22 -> 0 | BK29: =BJ29*$Y$4*$BM$22 -> 0 | BL29: =SUM(BJ29:BK29) -> 0 | BP29: =U29*IF(L29<VLOOKUP($C$5,DANE!$J$3:$N$14,4,FALSE),VLOOKUP($C$5,DANE!$J$3:$N$14,4,FALSE),L29) -> 0 | BQ29: =BP29*$Y$4 -> 0 | BR29: =U29*$Y$16 -> 0 | BS29: =SUM(BP29:BQ29) -> 0
B30: TRAINING | C30: 75 | P30: =IFERROR(IF(Q30="tak",$C$8/8*7*K30,K30*$C$8),"") -> 0 | W30: =IF(AND(SUM(M30:O30)<P30,(SUM(M30:O30)>0)),"TARGET: NIEDOGODZINY",IF(SUM(M30:O30)>P30,"TARGET: NADGODZINY",IF(AND(SUM(S30:U30)<P30,(SUM(S30:U30)>0)),"ESTIMATION: NIEDOGODZINY",IF(SUM(S30:U30)>P30,"ESTIMATION: NADGODZINY","-")))) -> - | Y30: =IF(OR(J30="KP",J30="BT",J30="LOBBY",J30="B"),(L30*1.1948)+0.7,"-") -> - | AB30: =IF(L30<VLOOKUP($C$5,DANE!$J$3:$N$14,4,FALSE),VLOOKUP($C$5,DANE!$J$3:$N$14,4,FALSE)*M30,L30*M30) -> 0 | AD30: =AB30*$Y$4 -> 0 | AE30: =AB30*$Y$6 -> 0 | AF30: =M30*$Y$16 -> 0 | AG30: =K30*$Y$13 -> 0 | AJ30: =SUM(AB30:AG30) -> 0 | AM30: =N30*IF(L30<VLOOKUP($C$5,DANE!$J$3:$N$14,4,FALSE),VLOOKUP($C$5,DANE!$J$3:$N$14,4,FALSE),L30)*$AP$22 -> 0 | AN30: =AM30*$Y$4*$AP$22 -> 0 | AO30: =SUM(AM30:AN30) -> 0 | AS30: =O30*IF(L30<VLOOKUP($C$5,DANE!$J$3:$N$14,4,FALSE),VLOOKUP($C$5,DANE!$J$3:$N$14,4,FALSE),L30) -> 0 | AT30: =AS30*$Y$4 -> 0 | AU30: =O30*$Y$16 -> 0 | AV30: =SUM(AS30:AT30) -> 0 | AY30: =IF(L30<VLOOKUP($C$5,DANE!$J$3:$N$14,4,FALSE),VLOOKUP($C$5,DANE!$J$3:$N$14,4,FALSE)*S30,L30*S30) -> 0 | BA30: =AY30*$Y$4 -> 0 | BB30: =AY30*$Y$6 -> 0 | BC30: =S30*$Y$16 -> 0 | BD30: =K30*$Y$13 -> 0 | BG30: =SUM(AY30:BD30) -> 0 | BJ30: =T30*IF(L30<VLOOKUP($C$5,DANE!$J$3:$N$14,4,FALSE),VLOOKUP($C$5,DANE!$J$3:$N$14,4,FALSE),L30)*$BM$22 -> 0 | BK30: =BJ30*$Y$4*$BM$22 -> 0 | BL30: =SUM(BJ30:BK30) -> 0 | BP30: =U30*IF(L30<VLOOKUP($C$5,DANE!$J$3:$N$14,4,FALSE),VLOOKUP($C$5,DANE!$J$3:$N$14,4,FALSE),L30) -> 0 | BQ30: =BP30*$Y$4 -> 0 | BR30: =U30*$Y$16 -> 0 | BS30: =SUM(BP30:BQ30) -> 0
P31: =IFERROR(IF(Q31="tak",$C$8/8*7*K31,K31*$C$8),"") -> 0 | W31: =IF(AND(SUM(M31:O31)<P31,(SUM(M31:O31)>0)),"TARGET: NIEDOGODZINY",IF(SUM(M31:O31)>P31,"TARGET: NADGODZINY",IF(AND(SUM(S31:U31)<P31,(SUM(S31:U31)>0)),"ESTIMATION: NIEDOGODZINY",IF(SUM(S31:U31)>P31,"ESTIMATION: NADGODZINY","-")))) -> - | Y31: =IF(OR(J31="KP",J31="BT",J31="LOBBY",J31="B"),(L31*1.1948)+0.7,"-") -> - | AB31: =IF(L31<VLOOKUP($C$5,DANE!$J$3:$N$14,4,FALSE),VLOOKUP($C$5,DANE!$J$3:$N$14,4,FALSE)*M31,L31*M31) -> 0 | AD31: =AB31*$Y$4 -> 0 | AE31: =AB31*$Y$6 -> 0 | AF31: =M31*$Y$16 -> 0 | AG31: =K31*$Y$13 -> 0 | AJ31: =SUM(AB31:AG31) -> 0 | AM31: =N31*IF(L31<VLOOKUP($C$5,DANE!$J$3:$N$14,4,FALSE),VLOOKUP($C$5,DANE!$J$3:$N$14,4,FALSE),L31)*$AP$22 -> 0 | AN31: =AM31*$Y$4*$AP$22 -> 0 | AO31: =SUM(AM31:AN31) -> 0 | AS31: =O31*IF(L31<VLOOKUP($C$5,DANE!$J$3:$N$14,4,FALSE),VLOOKUP($C$5,DANE!$J$3:$N$14,4,FALSE),L31) -> 0 | AT31: =AS31*$Y$4 -> 0 | AU31: =O31*$Y$16 -> 0 | AV31: =SUM(AS31:AT31) -> 0 | AY31: =IF(L31<VLOOKUP($C$5,DANE!$J$3:$N$14,4,FALSE),VLOOKUP($C$5,DANE!$J$3:$N$14,4,FALSE)*S31,L31*S31) -> 0 | BA31: =AY31*$Y$4 -> 0 | BB31: =AY31*$Y$6 -> 0 | BC31: =S31*$Y$16 -> 0 | BD31: =K31*$Y$13 -> 0 | BG31: =SUM(AY31:BD31) -> 0 | BJ31: =T31*IF(L31<VLOOKUP($C$5,DANE!$J$3:$N$14,4,FALSE),VLOOKUP($C$5,DANE!$J$3:$N$14,4,FALSE),L31)*$BM$22 -> 0 | BK31: =BJ31*$Y$4*$BM$22 -> 0 | BL31: =SUM(BJ31:BK31) -> 0 | BP31: =U31*IF(L31<VLOOKUP($C$5,DANE!$J$3:$N$14,4,FALSE),VLOOKUP($C$5,DANE!$J$3:$N$14,4,FALSE),L31) -> 0 | BQ31: =BP31*$Y$4 -> 0 | BR31: =U31*$Y$16 -> 0 | BS31: =SUM(BP31:BQ31) -> 0
B32: MATRIX PLAN | C32: Plan A | P32: =IFERROR(IF(Q32="tak",$C$8/8*7*K32,K32*$C$8),"") -> 0 | W32: =IF(AND(SUM(M32:O32)<P32,(SUM(M32:O32)>0)),"TARGET: NIEDOGODZINY",IF(SUM(M32:O32)>P32,"TARGET: NADGODZINY",IF(AND(SUM(S32:U32)<P32,(SUM(S32:U32)>0)),"ESTIMATION: NIEDOGODZINY",IF(SUM(S32:U32)>P32,"ESTIMATION: NADGODZINY","-")))) -> - | Y32: =IF(OR(J32="KP",J32="BT",J32="LOBBY",J32="B"),(L32*1.1948)+0.7,"-") -> - | AB32: =IF(L32<VLOOKUP($C$5,DANE!$J$3:$N$14,4,FALSE),VLOOKUP($C$5,DANE!$J$3:$N$14,4,FALSE)*M32,L32*M32) -> 0 | AD32: =AB32*$Y$4 -> 0 | AE32: =AB32*$Y$6 -> 0 | AF32: =M32*$Y$16 -> 0 | AG32: =K32*$Y$13 -> 0 | AJ32: =SUM(AB32:AG32) -> 0 | AM32: =N32*IF(L32<VLOOKUP($C$5,DANE!$J$3:$N$14,4,FALSE),VLOOKUP($C$5,DANE!$J$3:$N$14,4,FALSE),L32)*$AP$22 -> 0 | AN32: =AM32*$Y$4*$AP$22 -> 0 | AO32: =SUM(AM32:AN32) -> 0 | AS32: =O32*IF(L32<VLOOKUP($C$5,DANE!$J$3:$N$14,4,FALSE),VLOOKUP($C$5,DANE!$J$3:$N$14,4,FALSE),L32) -> 0 | AT32: =AS32*$Y$4 -> 0 | AU32: =O32*$Y$16 -> 0 | AV32: =SUM(AS32:AT32) -> 0 | AY32: =IF(L32<VLOOKUP($C$5,DANE!$J$3:$N$14,4,FALSE),VLOOKUP($C$5,DANE!$J$3:$N$14,4,FALSE)*S32,L32*S32) -> 0 | BA32: =AY32*$Y$4 -> 0 | BB32: =AY32*$Y$6 -> 0 | BC32: =S32*$Y$16 -> 0 | BD32: =K32*$Y$13 -> 0 | BG32: =SUM(AY32:BD32) -> 0 | BJ32: =T32*IF(L32<VLOOKUP($C$5,DANE!$J$3:$N$14,4,FALSE),VLOOKUP($C$5,DANE!$J$3:$N$14,4,FALSE),L32)*$BM$22 -> 0 | BK32: =BJ32*$Y$4*$BM$22 -> 0 | BL32: =SUM(BJ32:BK32) -> 0 | BP32: =U32*IF(L32<VLOOKUP($C$5,DANE!$J$3:$N$14,4,FALSE),VLOOKUP($C$5,DANE!$J$3:$N$14,4,FALSE),L32) -> 0 | BQ32: =BP32*$Y$4 -> 0 | BR32: =U32*$Y$16 -> 0 | BS32: =SUM(BP32:BQ32) -> 0
B33: TPLH SUGGESTED | C33: =IFERROR(($C$11/$C$7)/(($C$11/$C$7)/((($C$11/$C$7)/$C$13)*DANE!$R$2+DANE!$S$2)),"") | D33: =IFERROR(HLOOKUP($C$5,'TPLH PLAN'!$B$1:$M$2,2,FALSE),"") -> 0 | E33: =IFERROR(E11/E36,"") -> 5.6609279 | F33: =IFERROR(F11/F36,"") | P33: =IFERROR(IF(Q33="tak",$C$8/8*7*K33,K33*$C$8),"") -> 0 | W33: =IF(AND(SUM(M33:O33)<P33,(SUM(M33:O33)>0)),"TARGET: NIEDOGODZINY",IF(SUM(M33:O33)>P33,"TARGET: NADGODZINY",IF(AND(SUM(S33:U33)<P33,(SUM(S33:U33)>0)),"ESTIMATION: NIEDOGODZINY",IF(SUM(S33:U33)>P33,"ESTIMATION: NADGODZINY","-")))) -> - | Y33: =IF(OR(J33="KP",J33="BT",J33="LOBBY",J33="B"),(L33*1.1948)+0.7,"-") -> - | AB33: =IF(L33<VLOOKUP($C$5,DANE!$J$3:$N$14,4,FALSE),VLOOKUP($C$5,DANE!$J$3:$N$14,4,FALSE)*M33,L33*M33) -> 0 | AD33: =AB33*$Y$4 -> 0 | AE33: =AB33*$Y$6 -> 0 | AF33: =M33*$Y$16 -> 0 | AG33: =K33*$Y$13 -> 0 | AJ33: =SUM(AB33:AG33) -> 0 | AM33: =N33*IF(L33<VLOOKUP($C$5,DANE!$J$3:$N$14,4,FALSE),VLOOKUP($C$5,DANE!$J$3:$N$14,4,FALSE),L33)*$AP$22 -> 0 | AN33: =AM33*$Y$4*$AP$22 -> 0 | AO33: =SUM(AM33:AN33) -> 0 | AS33: =O33*IF(L33<VLOOKUP($C$5,DANE!$J$3:$N$14,4,FALSE),VLOOKUP($C$5,DANE!$J$3:$N$14,4,FALSE),L33) -> 0 | AT33: =AS33*$Y$4 -> 0 | AU33: =O33*$Y$16 -> 0 | AV33: =SUM(AS33:AT33) -> 0 | AY33: =IF(L33<VLOOKUP($C$5,DANE!$J$3:$N$14,4,FALSE),VLOOKUP($C$5,DANE!$J$3:$N$14,4,FALSE)*S33,L33*S33) -> 0 | BA33: =AY33*$Y$4 -> 0 | BB33: =AY33*$Y$6 -> 0 | BC33: =S33*$Y$16 -> 0 | BD33: =K33*$Y$13 -> 0 | BG33: =SUM(AY33:BD33) -> 0 | BJ33: =T33*IF(L33<VLOOKUP($C$5,DANE!$J$3:$N$14,4,FALSE),VLOOKUP($C$5,DANE!$J$3:$N$14,4,FALSE),L33)*$BM$22 -> 0 | BK33: =BJ33*$Y$4*$BM$22 -> 0 | BL33: =SUM(BJ33:BK33) -> 0 | BP33: =U33*IF(L33<VLOOKUP($C$5,DANE!$J$3:$N$14,4,FALSE),VLOOKUP($C$5,DANE!$J$3:$N$14,4,FALSE),L33) -> 0 | BQ33: =BP33*$Y$4 -> 0 | BR33: =U33*$Y$16 -> 0 | BS33: =SUM(BP33:BQ33) -> 0
P34: =IFERROR(IF(Q34="tak",$C$8/8*7*K34,K34*$C$8),"") -> 0 | W34: =IF(AND(SUM(M34:O34)<P34,(SUM(M34:O34)>0)),"TARGET: NIEDOGODZINY",IF(SUM(M34:O34)>P34,"TARGET: NADGODZINY",IF(AND(SUM(S34:U34)<P34,(SUM(S34:U34)>0)),"ESTIMATION: NIEDOGODZINY",IF(SUM(S34:U34)>P34,"ESTIMATION: NADGODZINY","-")))) -> - | Y34: =IF(OR(J34="KP",J34="BT",J34="LOBBY",J34="B"),(L34*1.1948)+0.7,"-") -> - | AB34: =IF(L34<VLOOKUP($C$5,DANE!$J$3:$N$14,4,FALSE),VLOOKUP($C$5,DANE!$J$3:$N$14,4,FALSE)*M34,L34*M34) -> 0 | AD34: =AB34*$Y$4 -> 0 | AE34: =AB34*$Y$6 -> 0 | AF34: =M34*$Y$16 -> 0 | AG34: =K34*$Y$13 -> 0 | AJ34: =SUM(AB34:AG34) -> 0 | AM34: =N34*IF(L34<VLOOKUP($C$5,DANE!$J$3:$N$14,4,FALSE),VLOOKUP($C$5,DANE!$J$3:$N$14,4,FALSE),L34)*$AP$22 -> 0 | AN34: =AM34*$Y$4*$AP$22 -> 0 | AO34: =SUM(AM34:AN34) -> 0 | AS34: =O34*IF(L34<VLOOKUP($C$5,DANE!$J$3:$N$14,4,FALSE),VLOOKUP($C$5,DANE!$J$3:$N$14,4,FALSE),L34) -> 0 | AT34: =AS34*$Y$4 -> 0 | AU34: =O34*$Y$16 -> 0 | AV34: =SUM(AS34:AT34) -> 0 | AY34: =IF(L34<VLOOKUP($C$5,DANE!$J$3:$N$14,4,FALSE),VLOOKUP($C$5,DANE!$J$3:$N$14,4,FALSE)*S34,L34*S34) -> 0 | BA34: =AY34*$Y$4 -> 0 | BB34: =AY34*$Y$6 -> 0 | BC34: =S34*$Y$16 -> 0 | BD34: =K34*$Y$13 -> 0 | BG34: =SUM(AY34:BD34) -> 0 | BJ34: =T34*IF(L34<VLOOKUP($C$5,DANE!$J$3:$N$14,4,FALSE),VLOOKUP($C$5,DANE!$J$3:$N$14,4,FALSE),L34)*$BM$22 -> 0 | BK34: =BJ34*$Y$4*$BM$22 -> 0 | BL34: =SUM(BJ34:BK34) -> 0 | BP34: =U34*IF(L34<VLOOKUP($C$5,DANE!$J$3:$N$14,4,FALSE),VLOOKUP($C$5,DANE!$J$3:$N$14,4,FALSE),L34) -> 0 | BQ34: =BP34*$Y$4 -> 0 | BR34: =U34*$Y$16 -> 0 | BS34: =SUM(BP34:BQ34) -> 0
B35: TPLH TARGET | C35: 6.6 | P35: =IFERROR(IF(Q35="tak",$C$8/8*7*K35,K35*$C$8),"") -> 0 | W35: =IF(AND(SUM(M35:O35)<P35,(SUM(M35:O35)>0)),"TARGET: NIEDOGODZINY",IF(SUM(M35:O35)>P35,"TARGET: NADGODZINY",IF(AND(SUM(S35:U35)<P35,(SUM(S35:U35)>0)),"ESTIMATION: NIEDOGODZINY",IF(SUM(S35:U35)>P35,"ESTIMATION: NADGODZINY","-")))) -> - | Y35: =IF(OR(J35="KP",J35="BT",J35="LOBBY",J35="B"),(L35*1.1948)+0.7,"-") -> - | AB35: =IF(L35<VLOOKUP($C$5,DANE!$J$3:$N$14,4,FALSE),VLOOKUP($C$5,DANE!$J$3:$N$14,4,FALSE)*M35,L35*M35) -> 0 | AD35: =AB35*$Y$4 -> 0 | AE35: =AB35*$Y$6 -> 0 | AF35: =M35*$Y$16 -> 0 | AG35: =K35*$Y$13 -> 0 | AJ35: =SUM(AB35:AG35) -> 0 | AM35: =N35*IF(L35<VLOOKUP($C$5,DANE!$J$3:$N$14,4,FALSE),VLOOKUP($C$5,DANE!$J$3:$N$14,4,FALSE),L35)*$AP$22 -> 0 | AN35: =AM35*$Y$4*$AP$22 -> 0 | AO35: =SUM(AM35:AN35) -> 0 | AS35: =O35*IF(L35<VLOOKUP($C$5,DANE!$J$3:$N$14,4,FALSE),VLOOKUP($C$5,DANE!$J$3:$N$14,4,FALSE),L35) -> 0 | AT35: =AS35*$Y$4 -> 0 | AU35: =O35*$Y$16 -> 0 | AV35: =SUM(AS35:AT35) -> 0 | AY35: =IF(L35<VLOOKUP($C$5,DANE!$J$3:$N$14,4,FALSE),VLOOKUP($C$5,DANE!$J$3:$N$14,4,FALSE)*S35,L35*S35) -> 0 | BA35: =AY35*$Y$4 -> 0 | BB35: =AY35*$Y$6 -> 0 | BC35: =S35*$Y$16 -> 0 | BD35: =K35*$Y$13 -> 0 | BG35: =SUM(AY35:BD35) -> 0 | BJ35: =T35*IF(L35<VLOOKUP($C$5,DANE!$J$3:$N$14,4,FALSE),VLOOKUP($C$5,DANE!$J$3:$N$14,4,FALSE),L35)*$BM$22 -> 0 | BK35: =BJ35*$Y$4*$BM$22 -> 0 | BL35: =SUM(BJ35:BK35) -> 0 | BP35: =U35*IF(L35<VLOOKUP($C$5,DANE!$J$3:$N$14,4,FALSE),VLOOKUP($C$5,DANE!$J$3:$N$14,4,FALSE),L35) -> 0 | BQ35: =BP35*$Y$4 -> 0 | BR35: =U35*$Y$16 -> 0 | BS35: =SUM(BP35:BQ35) -> 0
B36: TOTAL WORKING HOURS | C36: =IFERROR(M18+M41+M66,"") -> 1760 | E36: =IFERROR(S18+S41+S66,"") -> 1713.5 | P36: =IFERROR(IF(Q36="tak",$C$8/8*7*K36,K36*$C$8),"") -> 0 | W36: =IF(AND(SUM(M36:O36)<P36,(SUM(M36:O36)>0)),"TARGET: NIEDOGODZINY",IF(SUM(M36:O36)>P36,"TARGET: NADGODZINY",IF(AND(SUM(S36:U36)<P36,(SUM(S36:U36)>0)),"ESTIMATION: NIEDOGODZINY",IF(SUM(S36:U36)>P36,"ESTIMATION: NADGODZINY","-")))) -> - | Y36: =IF(OR(J36="KP",J36="BT",J36="LOBBY",J36="B"),(L36*1.1948)+0.7,"-") -> - | AB36: =IF(L36<VLOOKUP($C$5,DANE!$J$3:$N$14,4,FALSE),VLOOKUP($C$5,DANE!$J$3:$N$14,4,FALSE)*M36,L36*M36) -> 0 | AD36: =AB36*$Y$4 -> 0 | AE36: =AB36*$Y$6 -> 0 | AF36: =M36*$Y$16 -> 0 | AG36: =K36*$Y$13 -> 0 | AJ36: =SUM(AB36:AG36) -> 0 | AM36: =N36*IF(L36<VLOOKUP($C$5,DANE!$J$3:$N$14,4,FALSE),VLOOKUP($C$5,DANE!$J$3:$N$14,4,FALSE),L36)*$AP$22 -> 0 | AN36: =AM36*$Y$4*$AP$22 -> 0 | AO36: =SUM(AM36:AN36) -> 0 | AS36: =O36*IF(L36<VLOOKUP($C$5,DANE!$J$3:$N$14,4,FALSE),VLOOKUP($C$5,DANE!$J$3:$N$14,4,FALSE),L36) -> 0 | AT36: =AS36*$Y$4 -> 0 | AU36: =O36*$Y$16 -> 0 | AV36: =SUM(AS36:AT36) -> 0 | AY36: =IF(L36<VLOOKUP($C$5,DANE!$J$3:$N$14,4,FALSE),VLOOKUP($C$5,DANE!$J$3:$N$14,4,FALSE)*S36,L36*S36) -> 0 | BA36: =AY36*$Y$4 -> 0 | BB36: =AY36*$Y$6 -> 0 | BC36: =S36*$Y$16 -> 0 | BD36: =K36*$Y$13 -> 0 | BG36: =SUM(AY36:BD36) -> 0 | BJ36: =T36*IF(L36<VLOOKUP($C$5,DANE!$J$3:$N$14,4,FALSE),VLOOKUP($C$5,DANE!$J$3:$N$14,4,FALSE),L36)*$BM$22 -> 0 | BK36: =BJ36*$Y$4*$BM$22 -> 0 | BL36: =SUM(BJ36:BK36) -> 0 | BP36: =U36*IF(L36<VLOOKUP($C$5,DANE!$J$3:$N$14,4,FALSE),VLOOKUP($C$5,DANE!$J$3:$N$14,4,FALSE),L36) -> 0 | BQ36: =BP36*$Y$4 -> 0 | BR36: =U36*$Y$16 -> 0 | BS36: =SUM(BP36:BQ36) -> 0
P37: =IFERROR(IF(Q37="tak",$C$8/8*7*K37,K37*$C$8),"") -> 0 | W37: =IF(AND(SUM(M37:O37)<P37,(SUM(M37:O37)>0)),"TARGET: NIEDOGODZINY",IF(SUM(M37:O37)>P37,"TARGET: NADGODZINY",IF(AND(SUM(S37:U37)<P37,(SUM(S37:U37)>0)),"ESTIMATION: NIEDOGODZINY",IF(SUM(S37:U37)>P37,"ESTIMATION: NADGODZINY","-")))) -> - | Y37: =IF(OR(J37="KP",J37="BT",J37="LOBBY",J37="B"),(L37*1.1948)+0.7,"-") -> - | AB37: =IF(L37<VLOOKUP($C$5,DANE!$J$3:$N$14,4,FALSE),VLOOKUP($C$5,DANE!$J$3:$N$14,4,FALSE)*M37,L37*M37) -> 0 | AD37: =AB37*$Y$4 -> 0 | AE37: =AB37*$Y$6 -> 0 | AF37: =M37*$Y$16 -> 0 | AG37: =K37*$Y$13 -> 0 | AJ37: =SUM(AB37:AG37) -> 0 | AM37: =N37*IF(L37<VLOOKUP($C$5,DANE!$J$3:$N$14,4,FALSE),VLOOKUP($C$5,DANE!$J$3:$N$14,4,FALSE),L37)*$AP$22 -> 0 | AN37: =AM37*$Y$4*$AP$22 -> 0 | AO37: =SUM(AM37:AN37) -> 0 | AS37: =O37*IF(L37<VLOOKUP($C$5,DANE!$J$3:$N$14,4,FALSE),VLOOKUP($C$5,DANE!$J$3:$N$14,4,FALSE),L37) -> 0 | AT37: =AS37*$Y$4 -> 0 | AU37: =O37*$Y$16 -> 0 | AV37: =SUM(AS37:AT37) -> 0 | AY37: =IF(L37<VLOOKUP($C$5,DANE!$J$3:$N$14,4,FALSE),VLOOKUP($C$5,DANE!$J$3:$N$14,4,FALSE)*S37,L37*S37) -> 0 | BA37: =AY37*$Y$4 -> 0 | BB37: =AY37*$Y$6 -> 0 | BC37: =S37*$Y$16 -> 0 | BD37: =K37*$Y$13 -> 0 | BG37: =SUM(AY37:BD37) -> 0 | BJ37: =T37*IF(L37<VLOOKUP($C$5,DANE!$J$3:$N$14,4,FALSE),VLOOKUP($C$5,DANE!$J$3:$N$14,4,FALSE),L37)*$BM$22 -> 0 | BK37: =BJ37*$Y$4*$BM$22 -> 0 | BL37: =SUM(BJ37:BK37) -> 0 | BP37: =U37*IF(L37<VLOOKUP($C$5,DANE!$J$3:$N$14,4,FALSE),VLOOKUP($C$5,DANE!$J$3:$N$14,4,FALSE),L37) -> 0 | BQ37: =BP37*$Y$4 -> 0 | BR37: =U37*$Y$16 -> 0 | BS37: =SUM(BP37:BQ37) -> 0
B38: WORKING HOURS BUDGET | C38: =IFERROR(C11/C35,"WPROWADŹ TPLH TARGET") -> 1651.5152 | D38: =IFERROR(D11/D33,"-") -> - | P38: =IFERROR(IF(Q38="tak",$C$8/8*7*K38,K38*$C$8),"") -> 0 | W38: =IF(AND(SUM(M38:O38)<P38,(SUM(M38:O38)>0)),"TARGET: NIEDOGODZINY",IF(SUM(M38:O38)>P38,"TARGET: NADGODZINY",IF(AND(SUM(S38:U38)<P38,(SUM(S38:U38)>0)),"ESTIMATION: NIEDOGODZINY",IF(SUM(S38:U38)>P38,"ESTIMATION: NADGODZINY","-")))) -> - | Y38: =IF(OR(J38="KP",J38="BT",J38="LOBBY",J38="B"),(L38*1.1948)+0.7,"-") -> - | AB38: =IF(L38<VLOOKUP($C$5,DANE!$J$3:$N$14,4,FALSE),VLOOKUP($C$5,DANE!$J$3:$N$14,4,FALSE)*M38,L38*M38) -> 0 | AD38: =AB38*$Y$4 -> 0 | AE38: =AB38*$Y$6 -> 0 | AF38: =M38*$Y$16 -> 0 | AG38: =K38*$Y$13 -> 0 | AJ38: =SUM(AB38:AG38) -> 0 | AM38: =N38*IF(L38<VLOOKUP($C$5,DANE!$J$3:$N$14,4,FALSE),VLOOKUP($C$5,DANE!$J$3:$N$14,4,FALSE),L38)*$AP$22 -> 0 | AN38: =AM38*$Y$4*$AP$22 -> 0 | AO38: =SUM(AM38:AN38) -> 0 | AS38: =O38*IF(L38<VLOOKUP($C$5,DANE!$J$3:$N$14,4,FALSE),VLOOKUP($C$5,DANE!$J$3:$N$14,4,FALSE),L38) -> 0 | AT38: =AS38*$Y$4 -> 0 | AU38: =O38*$Y$16 -> 0 | AV38: =SUM(AS38:AT38) -> 0 | AY38: =IF(L38<VLOOKUP($C$5,DANE!$J$3:$N$14,4,FALSE),VLOOKUP($C$5,DANE!$J$3:$N$14,4,FALSE)*S38,L38*S38) -> 0 | BA38: =AY38*$Y$4 -> 0 | BB38: =AY38*$Y$6 -> 0 | BC38: =S38*$Y$16 -> 0 | BD38: =K38*$Y$13 -> 0 | BG38: =SUM(AY38:BD38) -> 0 | BJ38: =T38*IF(L38<VLOOKUP($C$5,DANE!$J$3:$N$14,4,FALSE),VLOOKUP($C$5,DANE!$J$3:$N$14,4,FALSE),L38)*$BM$22 -> 0 | BK38: =BJ38*$Y$4*$BM$22 -> 0 | BL38: =SUM(BJ38:BK38) -> 0 | BP38: =U38*IF(L38<VLOOKUP($C$5,DANE!$J$3:$N$14,4,FALSE),VLOOKUP($C$5,DANE!$J$3:$N$14,4,FALSE),L38) -> 0 | BQ38: =BP38*$Y$4 -> 0 | BR38: =U38*$Y$16 -> 0 | BS38: =SUM(BP38:BQ38) -> 0
P39: =IFERROR(IF(Q39="tak",$C$8/8*7*K39,K39*$C$8),"") -> 0 | W39: =IF(AND(SUM(M39:O39)<P39,(SUM(M39:O39)>0)),"TARGET: NIEDOGODZINY",IF(SUM(M39:O39)>P39,"TARGET: NADGODZINY",IF(AND(SUM(S39:U39)<P39,(SUM(S39:U39)>0)),"ESTIMATION: NIEDOGODZINY",IF(SUM(S39:U39)>P39,"ESTIMATION: NADGODZINY","-")))) -> - | Y39: =IF(OR(J39="KP",J39="BT",J39="LOBBY",J39="B"),(L39*1.1948)+0.7,"-") -> - | AB39: =IF(L39<VLOOKUP($C$5,DANE!$J$3:$N$14,4,FALSE),VLOOKUP($C$5,DANE!$J$3:$N$14,4,FALSE)*M39,L39*M39) -> 0 | AD39: =AB39*$Y$4 -> 0 | AE39: =AB39*$Y$6 -> 0 | AF39: =M39*$Y$16 -> 0 | AG39: =K39*$Y$13 -> 0 | AJ39: =SUM(AB39:AG39) -> 0 | AM39: =N39*IF(L39<VLOOKUP($C$5,DANE!$J$3:$N$14,4,FALSE),VLOOKUP($C$5,DANE!$J$3:$N$14,4,FALSE),L39)*$AP$22 -> 0 | AN39: =AM39*$Y$4*$AP$22 -> 0 | AO39: =SUM(AM39:AN39) -> 0 | AS39: =O39*IF(L39<VLOOKUP($C$5,DANE!$J$3:$N$14,4,FALSE),VLOOKUP($C$5,DANE!$J$3:$N$14,4,FALSE),L39) -> 0 | AT39: =AS39*$Y$4 -> 0 | AU39: =O39*$Y$16 -> 0 | AV39: =SUM(AS39:AT39) -> 0 | AY39: =IF(L39<VLOOKUP($C$5,DANE!$J$3:$N$14,4,FALSE),VLOOKUP($C$5,DANE!$J$3:$N$14,4,FALSE)*S39,L39*S39) -> 0 | BA39: =AY39*$Y$4 -> 0 | BB39: =AY39*$Y$6 -> 0 | BC39: =S39*$Y$16 -> 0 | BD39: =K39*$Y$13 -> 0 | BG39: =SUM(AY39:BD39) -> 0 | BJ39: =T39*IF(L39<VLOOKUP($C$5,DANE!$J$3:$N$14,4,FALSE),VLOOKUP($C$5,DANE!$J$3:$N$14,4,FALSE),L39)*$BM$22 -> 0 | BK39: =BJ39*$Y$4*$BM$22 -> 0 | BL39: =SUM(BJ39:BK39) -> 0 | BP39: =U39*IF(L39<VLOOKUP($C$5,DANE!$J$3:$N$14,4,FALSE),VLOOKUP($C$5,DANE!$J$3:$N$14,4,FALSE),L39) -> 0 | BQ39: =BP39*$Y$4 -> 0 | BR39: =U39*$Y$16 -> 0 | BS39: =SUM(BP39:BQ39) -> 0
P40: =IFERROR(IF(Q40="tak",$C$8/8*7*K40,K40*$C$8),"") -> 0 | W40: =IF(AND(SUM(M40:O40)<P40,(SUM(M40:O40)>0)),"TARGET: NIEDOGODZINY",IF(SUM(M40:O40)>P40,"TARGET: NADGODZINY",IF(AND(SUM(S40:U40)<P40,(SUM(S40:U40)>0)),"ESTIMATION: NIEDOGODZINY",IF(SUM(S40:U40)>P40,"ESTIMATION: NADGODZINY","-")))) -> - | Y40: =IF(OR(J40="KP",J40="BT",J40="LOBBY",J40="B"),(L40*1.1948)+0.7,"-") -> - | AB40: =IF(L40<VLOOKUP($C$5,DANE!$J$3:$N$14,4,FALSE),VLOOKUP($C$5,DANE!$J$3:$N$14,4,FALSE)*M40,L40*M40) -> 0 | AD40: =AB40*$Y$4 -> 0 | AE40: =AB40*$Y$6 -> 0 | AF40: =M40*$Y$16 -> 0 | AG40: =K40*$Y$13 -> 0 | AJ40: =SUM(AB40:AG40) -> 0 | AM40: =N40*IF(L40<VLOOKUP($C$5,DANE!$J$3:$N$14,4,FALSE),VLOOKUP($C$5,DANE!$J$3:$N$14,4,FALSE),L40)*$AP$22 -> 0 | AN40: =AM40*$Y$4*$AP$22 -> 0 | AO40: =SUM(AM40:AN40) -> 0 | AS40: =O40*IF(L40<VLOOKUP($C$5,DANE!$J$3:$N$14,4,FALSE),VLOOKUP($C$5,DANE!$J$3:$N$14,4,FALSE),L40) -> 0 | AT40: =AS40*$Y$4 -> 0 | AU40: =O40*$Y$16 -> 0 | AV40: =SUM(AS40:AT40) -> 0 | AY40: =IF(L40<VLOOKUP($C$5,DANE!$J$3:$N$14,4,FALSE),VLOOKUP($C$5,DANE!$J$3:$N$14,4,FALSE)*S40,L40*S40) -> 0 | BA40: =AY40*$Y$4 -> 0 | BB40: =AY40*$Y$6 -> 0 | BC40: =S40*$Y$16 -> 0 | BD40: =K40*$Y$13 -> 0 | BG40: =SUM(AY40:BD40) -> 0 | BJ40: =T40*IF(L40<VLOOKUP($C$5,DANE!$J$3:$N$14,4,FALSE),VLOOKUP($C$5,DANE!$J$3:$N$14,4,FALSE),L40)*$BM$22 -> 0 | BK40: =BJ40*$Y$4*$BM$22 -> 0 | BL40: =SUM(BJ40:BK40) -> 0 | BP40: =U40*IF(L40<VLOOKUP($C$5,DANE!$J$3:$N$14,4,FALSE),VLOOKUP($C$5,DANE!$J$3:$N$14,4,FALSE),L40) -> 0 | BQ40: =BP40*$Y$4 -> 0 | BR40: =U40*$Y$16 -> 0 | BS40: =SUM(BP40:BQ40) -> 0
B41: Check what would be the TPLH improvement impact on your store COL | C41: TPLH improvement | D41: COL savings | E41: COL % influence | H41: UMOWA O PRACĘ TOTAL: | K41: =SUM(K22:K40) -> 1.25 | M41: =SUM(M22:M40) -> 220 | N41: =SUM(N22:N40) -> 0 | O41: =SUM(O22:O40) -> 0 | P41: =SUM(P22:P40) -> 220 | S41: =SUM(S22:S40) -> 205 | T41: =SUM(T22:T40) -> 0 | U41: =SUM(U22:U40) -> 0 | V41: =SUM(V22:V40) -> 0 | AB41: =SUM(AB22:AB40) -> 6822.2 | AD41: =SUM(AD22:AD40) -> 1154.9985 | AE41: =SUM(AE22:AE40) -> 173.9661 | AF41: =SUM(AF22:AF40) -> 187 | AG41: =SUM(AG22:AG40) -> 250 | AJ41: =SUM(AJ22:AJ40) -> 8588.1646 | AM41: =SUM(AM22:AM40) -> 0 | AN41: =SUM(AN22:AN40) -> 0 | AO41: =SUM(AO22:AO40) -> 0 | AS41: =SUM(AS22:AS40) -> 0 | AT41: =SUM(AT22:AT40) -> 0 | AU41: =SUM(AU22:AU40) -> 0 | AV41: =SUM(AV22:AV40) -> 0 | AY41: =SUM(AY22:AY40) -> 6359 | BA41: =SUM(BA22:BA40) -> 1076.5787 | BB41: =SUM(BB22:BB40) -> 162.1545 | BC41: =SUM(BC22:BC40) -> 174.25 | BD41: =SUM(BD22:BD40) -> 250 | BG41: =SUM(BG22:BG40) -> 8021.9832 | BJ41: =SUM(BJ22:BJ40) -> 0 | BK41: =SUM(BK22:BK40) -> 0 | BL41: =SUM(BL22:BL40) -> 0 | BP41: =SUM(BP22:BP40) -> 0 | BQ41: =SUM(BQ22:BQ40) -> 0 | BR41: =SUM(BR22:BR40) -> 0 | BS41: =SUM(BS22:BS40) -> 0
...

Sheet BONUS
B1: BONUS | C1: CAP | F1: BONUS MANAGERS
B2: SM | C2: 2250 | F2: SM | G2: =SUM(G11,G16) -> 0
B3: ASM | C3: 1000 | F3: ASM | G3: =SUM(H11,H16) -> 0
B4: SSV-PM | C4: 700 | F4: SSV-PM | G4: =SUM(I11,I16) -> 0
B5: SSV-FM | C5: 700 | F5: SSV-FM | G5: =SUM(J11,J16) -> 0
B7: =VLOOKUP(CALCULATOR!$C$5,DANE!B17:F28,3,FALSE) -> Sierpień | F7: SALES BONUS KALKULATOR
C8: AOP | D8: SALES | F8: SALES | H8: AOP | I8: index | J8: % of Cap
B9: STYCZEŃ | C9: =VLOOKUP($D$8,AOP!$A$2:$Z$100,VLOOKUP(B9,DANE!$B$17:$C$28,2,FALSE),FALSE) -> #N/A | F9: =IF(B7=B9,D9,IF(B7=B10,D10,IF(B7=B11,D11,IF(B7=B12,D12,IF(B7=B13,D13,IF(B7=B14,D14,IF(B7=B15,D15,IF(B7=B16,D16,IF(B7=B17,D17,IF(B7=B18,D18,IF(B7=B19,D19,IF(B7=B20,D20)))))))))))) -> 0 | H9: =IF(B7=B9,C9,IF(B7=B10,C10,IF(B7=B11,C11,IF(B7=B12,C12,IF(B7=B13,C13,IF(B7=B14,C14,IF(B7=B15,C15,IF(B7=B16,C16,IF(B7=B17,C17,IF(B7=B18,C18,IF(B7=B19,C19,IF(B7=B20,C20)))))))))))) -> #N/A | I9: =IFERROR(ROUND(F9/H9,2),0) -> 0 | J9: =IF(I9>F20,G20,IF(I9<F36,G36,VLOOKUP(I9,F20:G36,2,FALSE))) -> 0
B10: LUTY | C10: =VLOOKUP($D$8,AOP!$A$2:$Z$100,VLOOKUP(B10,DANE!$B$17:$C$28,2,FALSE),FALSE) -> #N/A | F10: BONUS FOR MANAGER | G10: =F2 -> SM | H10: =F3 -> ASM | I10: =F4 -> SSV-PM | J10: =F5 -> SSV-FM
B11: MARZEC | C11: =VLOOKUP($D$8,AOP!$A$2:$Z$100,VLOOKUP(B11,DANE!$B$17:$C$28,2,FALSE),FALSE) -> #N/A | G11: =IF($J$9=0,"brak premii",$C$2*$J$9) -> brak premii | H11: =IF($J$9=0,"brak premii",$C$3*$J$9) -> brak premii | I11: =IF($J$9=0,"brak premii",$C$4*$J$9) -> brak premii | J11: =IF($J$9=0,"brak premii",$C$5*$J$9) -> brak premii
B12: KWIECIEŃ | C12: =VLOOKUP($D$8,AOP!$A$2:$Z$100,VLOOKUP(B12,DANE!$B$17:$C$28,2,FALSE),FALSE) -> #N/A | F12: OPS profit BONUS KALKULATOR
B13: MAJ | C13: =VLOOKUP($D$8,AOP!$A$2:$Z$100,VLOOKUP(B13,DANE!$B$17:$C$28,2,FALSE),FALSE) -> #N/A | F13: OPS profit | H13: AOP | I13: index | J13: % of Cap
B14: CZERWIEC | C14: =VLOOKUP($D$8,AOP!$A$2:$Z$100,VLOOKUP(B14,DANE!$B$17:$C$28,2,FALSE),FALSE) -> #N/A | F14: =ROUND(IF(B7=B22,D22,IF(B7=B23,D23,IF(B7=B24,D24,IF(B7=B25,D25,IF(B7=B26,D26,IF(B7=B27,D27,IF(B7=B28,D28,IF(B7=B29,D29,IF(B7=B30,D30,IF(B7=B31,D31,IF(B7=B32,D32,IF(B7=B33,D33)))))))))))),3) -> 0 | H14: =IF(B7=B22,C22,IF(B7=B23,C23,IF(B7=B24,C24,IF(B7=B25,C25,IF(B7=B26,C26,IF(B7=B27,C27,IF(B7=B28,C28,IF(B7=B29,C29,IF(B7=B30,C30,IF(B7=B31,C31,IF(B7=B32,C32,IF(B7=B33,C33)))))))))))) -> #N/A | I14: =ROUND(IFERROR(F14/H14,0),2) -> 0 | J14: =IF(I14>H20,I20,IF(I14<H36,I36,VLOOKUP(I14,H20:I36,2,FALSE))) -> 0
B15: LIPIEC | C15: =VLOOKUP($D$8,AOP!$A$2:$Z$100,VLOOKUP(B15,DANE!$B$17:$C$28,2,FALSE),FALSE) -> #N/A | F15: BONUS FOR MANAGER | G15: =F2 -> SM | H15: =F3 -> ASM | I15: =F4 -> SSV-PM | J15: =F5 -> SSV-FM
B16: SIERPIEŃ | C16: =VLOOKUP($D$8,AOP!$A$2:$Z$100,VLOOKUP(B16,DANE!$B$17:$C$28,2,FALSE),FALSE) -> #N/A | G16: =IF($J$14=0,"brak premii",$C$2*$J$14) -> brak premii | H16: =IF($J$14=0,"brak premii",$C$3*$J$14) -> brak premii | I16: =IF($J$14=0,"brak premii",$C$4*$J$14) -> brak premii | J16: =IF($J$14=0,"brak premii",$C$5*$J$14) -> brak premii
B17: WRZESIEŃ | C17: =VLOOKUP($D$8,AOP!$A$2:$Z$100,VLOOKUP(B17,DANE!$B$17:$C$28,2,FALSE),FALSE) -> #N/A
B18: PAŹDZIERNIK | C18: =VLOOKUP($D$8,AOP!$A$2:$Z$100,VLOOKUP(B18,DANE!$B$17:$C$28,2,FALSE),FALSE) -> #N/A | F18: BONUS CALCULATIONS L2-L4
B19: LISTOPAD | C19: =VLOOKUP($D$8,AOP!$A$2:$Z$100,VLOOKUP(B19,DANE!$B$17:$C$28,2,FALSE),FALSE) -> #N/A | F19: Sales vs AOP | G19: % of Cap | H19: OPS profit vs AOP | I19: % of cap | J19: max % of cap
B20: GRUDZIEŃ | C20: =VLOOKUP($D$8,AOP!$A$2:$Z$100,VLOOKUP(B20,DANE!$B$17:$C$28,2,FALSE),FALSE) -> #N/A | F20: 1.1 | G20: 0.75 | H20: 1.1 | I20: 0.75 | J20: 1.5
C21: AOP | D21: OPS PROFIT | F21: 1.09 | G21: 0.73 | H21: 1.09 | I21: 0.72 | J21: 1.45
B22: STYCZEŃ | C22: =ROUND(VLOOKUP($D$21,AOP!$A$2:$Z$100,VLOOKUP(B22,DANE!$B$17:$E$28,4,FALSE),FALSE),3) -> #N/A | F22: 1.08 | G22: 0.7 | H22: 1.08 | I22: 0.7 | J22: 1.4
B23: LUTY | C23: =ROUND(VLOOKUP($D$21,AOP!$A$2:$Z$100,VLOOKUP(B23,DANE!$B$17:$E$28,4,FALSE),FALSE),3) -> #N/A | F23: 1.07 | G23: 0.68 | H23: 1.07 | I23: 0.67 | J23: 1.35
B24: MARZEC | C24: =ROUND(VLOOKUP($D$21,AOP!$A$2:$Z$100,VLOOKUP(B24,DANE!$B$17:$E$28,4,FALSE),FALSE),3) -> #N/A | F24: 1.06 | G24: 0.65 | H24: 1.06 | I24: 0.65 | J24: 1.3
B25: KWIECIEŃ | C25: =ROUND(VLOOKUP($D$21,AOP!$A$2:$Z$100,VLOOKUP(B25,DANE!$B$17:$E$28,4,FALSE),FALSE),3) -> #N/A | F25: 1.05 | G25: 0.63 | H25: 1.05 | I25: 0.62 | J25: 1.25
B26: MAJ | C26: =ROUND(VLOOKUP($D$21,AOP!$A$2:$Z$100,VLOOKUP(B26,DANE!$B$17:$E$28,4,FALSE),FALSE),3) -> #N/A | F26: 1.04 | G26: 0.6 | H26: 1.04 | I26: 0.6 | J26: 1.2
